Workbook

Sheet Bìa
A2: CTY CỔ PHẦN ĐẦU TƯ XÂY DỰNG | E2: CỘNG HÒA XÃ HỘI CHỦ NGHĨA VIỆT NAM
E3: Độc lập - Tự do - Hạnh phúc
E4: ______ ² ______
A13: HỒ SƠ QUYẾT TOÁN
C14: CÔNG TRÌNH : THI CÔNG ………………
C15: ĐỊA ĐIỂM: ………………
C16: CHỦ ĐẦU TƯ : ………………
C17: NHÀ THẦU : ………………..
A24: Tháng ….. năm 2024

Sheet PL SOAT XET
A1: PHỤ LỤC SOÁT XÉT
A2: =Bìa!C14 -> CÔNG TRÌNH : THI CÔNG ………………
A3: =Bìa!C15 -> ĐỊA ĐIỂM: ………………
A4: SỐ HỢP ĐỒNG: …………………
A5: STT | B5: NỘI DUNG CÔNG VIỆC | C5: ĐVT | D5: KHỐI LƯỢNG | G5: ĐƠN GIÁ | J5: THÀNH TIỀN | M5: CHÊNH LỆCH | O5: MÔ TẢ KỸ THUẬT | P5: HÃNG - XUẤT XỨ | Q5: GHI CHÚ | R5: KIỂM SOÁT HỒ SƠ ĐẦU VÀO | Y5: KIỂM SOÁT HỒ SƠ NGHIỆM THU CHẤT LƯỢNG
D6: HỢP ĐỒNG+PL | E6: THỰC HIỆN | F6: KIỂM SOÁT | G6: VẬT TƯ | H6: NHÂN CÔNG | I6: TỔNG CỘNG | J6: HỢP ĐỒNG+PL | K6: THỰC HIỆN | L6: KIỂM SOÁT | M6: KIỂM SOÁT - HỢP ĐỒNG | N6: KIỂM SOÁT - THỰC HIỆN | R6: Số BB nghiệm thu | S6: Khối lượng tổng | T6: Nhãn hiệu/Ncc theo Hợp đồng | U6: Nhãn hiệu/Ncc theo Hồ sơ | V6: BB giao hàng số | W6: CO/Xuất xưởng số | X6: CQ/Chứng nhận chất lượng số | Y6: Số Biên bản nghiệm thu | Z6: Bản vẽ thiết kế/hoàn công | AA6: Thí nghiệm đối chứng | AB6: TTr Chủ trương | AC6: Ghi chú
B7: Theo HĐ số 03/2022/HĐXD/HSG-HTC ký ngày 10/05/2022
A8: A | B8: HẠNG MỤC XÂY DỰNG | J8: =SUBTOTAL(9,J9:J38) -> 1.8342221e+09 | K8: =SUBTOTAL(9,K9:K38) -> #REF! | L8: =SUBTOTAL(9,L9:L38) -> #REF! | M8: =SUBTOTAL(9,M9:M38) -> #REF! | N8: =SUBTOTAL(9,N9:N38) -> #REF!
A9: 1 | B9: Chi phí Điện - Nước thi công | C9: gói | D9: 1 | E9: ='KL TONG HOP'!E8 -> 1 | F9: =IF(E9-D9>0,D9,E9) -> 1 | G9: 0 | H9: 0 | I9: =G9+H9 -> 0 | J9: =D9*I9 -> 0 | K9: =E9*I9 -> 0 | L9: =F9*(G9+H9) -> 0 | M9: =L9-J9 -> 0 | N9: =L9-K9 -> 0 | Q9: Giá đã bao gồm chi phí điện nước phục vụ thi công
A10: 2 | B10: Chi phí xin giấy phép xây dựng | C10: gói | D10: 1 | E10: ='KL TONG HOP'!E9 -> 1 | F10: =IF(E10-D10>0,D10,E10) -> 1 | G10: 0 | H10: 12100000 | I10: =G10+H10 -> 12100000 | J10: =D10*I10 -> 12100000 | K10: =E10*I10 -> 12100000 | L10: =F10*(G10+H10) -> 12100000 | M10: =L10-J10 -> 0 | N10: =L10-K10 -> 0
A11: 3 | B11: Tháo dỡ theo bản vẽ thiết kế được duyệt và theo yêu cầu của CĐT trong quá trình triển khai thi công,.... | C11: trọn gói | D11: 1 | E11: ='KL TONG HOP'!E10 -> 1 | F11: =IF(E11-D11>0,D11,E11) -> 1 | G11: 0 | H11: 60500000 | I11: =G11+H11 -> 60500000 | J11: =D11*I11 -> 60500000 | K11: =E11*I11 -> 60500000 | L11: =F11*(G11+H11) -> 60500000 | M11: =L11-J11 -> 0 | N11: =L11-K11 -> 0 | Y11: 03/NTCV/XD | Z11: KT-01;02;03;04
A12: 4 | B12: Vận chuyển rác thải, xà bần ra ngoài công trình | C12: gói | D12: 1 | E12: ='KL TONG HOP'!E11 -> 1 | F12: =IF(E12-D12>0,D12,E12) -> 1 | G12: 0 | H12: 36300000 | I12: =G12+H12 -> 36300000 | J12: =D12*I12 -> 36300000 | K12: =E12*I12 -> 36300000 | L12: =F12*(G12+H12) -> 36300000 | M12: =L12-J12 -> 0 | N12: =L12-K12 -> 0
A13: 5 | B13: Cạo, xủi vệ sinh lớp sơn tường cũ trong nhà | C13: m2 | D13: 1852.2149 | E13: ='KL TONG HOP'!E12 -> 1852.2149 | F13: =IF(E13-D13>0,D13,E13) -> 1852.2149 | G13: 0 | H13: 24200 | I13: =G13+H13 -> 24200 | J13: =D13*I13 -> 44823601 | K13: =E13*I13 -> 44823601 | L13: =F13*(G13+H13) -> 44823601 | M13: =L13-J13 -> 0 | N13: =L13-K13 -> 0 | Y13: 15/NTCV/XD | Z13: KT-01;02;03;04;14;15;18;19
A14: 6 | B14: Cạo, xủi vệ sinh lớp sơn tường cũ ngoài nhà | C14: m2 | D14: 1541.9158 | E14: ='KL TONG HOP'!E13 -> 1541.9158 | F14: ='Dien giai KL'!K146 -> 1485.7388 | G14: 0 | H14: 36300 | I14: =G14+H14 -> 36300 | J14: =D14*I14 -> 55971543 | K14: =E14*I14 -> 55971543 | L14: =F14*(G14+H14) -> 53932318 | M14: =L14-J14 -> -2039225.1 | N14: =L14-K14 -> -2039225.1 | Y14: 21/NTCV/XD 22/NTCV/XD 31/NTCV/XD | Z14: KT-01 HT-04;05;06;07
A15: 7 | B15: Vệ sinh nền sảnh trệt, cầu thang và đánh bóng lại đá lát nền hiện trạng | C15: gói | D15: 1 | E15: ='KL TONG HOP'!E14 -> 1 | F15: =IF(E15-D15>0,D15,E15) -> 1 | G15: 0 | H15: 12100000 | I15: =G15+H15 -> 12100000 | J15: =D15*I15 -> 12100000 | K15: =E15*I15 -> 12100000 | L15: =F15*(G15+H15) -> 12100000 | M15: =L15-J15 -> 0 | N15: =L15-K15 -> 0 | Y15: 65/NTCV/XD | Z15: KT-09;10;11;12;13
A16: 8 | B16: Vệ sinh và sơn PU tay vịn lan can cầu thang | C16: gói | D16: 1 | E16: ='KL TONG HOP'!E15 -> 1 | F16: =IF(E16-D16>0,D16,E16) -> 1 | G16: 0 | H16: 36300000 | I16: =G16+H16 -> 36300000 | J16: =D16*I16 -> 36300000 | K16: =E16*I16 -> 36300000 | L16: =F16*(G16+H16) -> 36300000 | M16: =L16-J16 -> 0 | N16: =L16-K16 -> 0 | Y16: 65/NTCV/XD | Z16: KT-09;10;11;12;13
A17: 9 | B17: Đục phá lớp gạch lát sàn, vữa lót nền tới lớp bê tông sàn hiện hữu (xử lý trước khi láng nền sàn) | C17: m2 | D17: 2211.2774 | E17: ='KL TONG HOP'!E16 -> 2211.2774 | F17: =IF(E17-D17>0,D17,E17) -> 2211.2774 | G17: 0 | H17: 60500 | I17: =G17+H17 -> 60500 | J17: =D17*I17 -> 1.3378228e+08 | K17: =E17*I17 -> 1.3378228e+08 | L17: =F17*(G17+H17) -> 1.3378228e+08 | M17: =L17-J17 -> 0 | N17: =L17-K17 -> 0 | Y17: 03/NTCV/XD | Z17: KT-09;10;11;12;13
A18: 10 | B18: Tháo dỡ cầu thang hiện hữu tầng 1, tầng 2, hoàn thiện mặt nền tới cao độ hiện trạng (Bao gồm Bê tông, ván khuôn, khoan cấy thép, cán nền, …) | C18: gói | D18: 1 | E18: ='KL TONG HOP'!E17 -> 1 | F18: =IF(E18-D18>0,D18,E18) -> 1 | G18: 0 | H18: 19360000 | I18: =G18+H18 -> 19360000 | J18: =D18*I18 -> 19360000 | K18: =E18*I18 -> 19360000 | L18: =F18*(G18+H18) -> 19360000 | M18: =L18-J18 -> 0 | N18: =L18-K18 -> 0 | Y18: 03/NTCV/XD | Z18: HT-02;03
A19: 11 | B19: Sơn dầm, trần, cột, tường trong nhà (bã mastic 02 lớp, sơn 01 lớp lót 02 lớp hoàn thiện) | C19: m2 | D19: 2641.5861 | E19: ='KL TONG HOP'!E18 -> #REF! | F19: =IF(E19-D19>0,D19,E19) -> #REF! | G19: 51912 | H19: 72600 | I19: =G19+H19 -> 124512 | J19: =D19*I19 -> 3.2890916e+08 | K19: =E19*I19 -> #REF! | L19: =F19*(G19+H19) -> #REF! | M19: =L19-J19 -> #REF! | N19: =L19-K19 -> #REF! | O19: Dulux | P19: Hoa Sen | Q19: Mua từ chuỗi hệ thống HS Home | R19: 03/NTVL | T19: Dulux | U19: KCC (Hoa Sen) | Y19: 44/NTCV/XD 47/NTCV/XD 59/NTCV/XD 64/NTCV/XD 68/NTCV/XD | Z19: KT-01;02;03;04;14;15;18;19;21
B20: Bột trét trong | C20: bao 40kg | V20: HĐ:00001727 HĐ:00003109 HĐ:00012690 HĐ:00014569 | W20: HĐ:00001727 HĐ:00003109 HĐ:00012690 HĐ:00014569 | X20: HĐ:00001727 HĐ:00003109 HĐ:00012690 HĐ:00014569
B21: Sơn lót trong | C21: thùng 18L | V21: HĐ:00001072 | W21: HĐ:00001072 | X21: HĐ:00001072
B22: Sơn hoàn thiện trong | C22: thùng 18L | V22: HĐ:00007832 | W22: HĐ:00007832 | X22: HĐ:00007832
A23: 12 | B23: Sơn dầm, trần, cột, tường ngoài nhà (bã mastic 02 lớp, sơn 01 lớp lót 02 lớp hoàn thiện) | C23: m2 | D23: 1541.9158 | E23: ='KL TONG HOP'!E19 -> 1541.9158 | F23: =IF(E23-D23>0,D23,E23) -> 1541.9158 | G23: 69216 | H23: 84700 | I23: =G23+H23 -> 153916 | J23: =D23*I23 -> 2.3732551e+08 | K23: =E23*I23 -> 2.3732551e+08 | L23: =F23*(G23+H23) -> 2.3732551e+08 | M23: =L23-J23 -> 0 | N23: =L23-K23 -> 0 | O23: Dulux - mastic và sơn chống thấm | P23: Hoa Sen | Q23: Mua từ chuỗi hệ thống HS Home | R23: 17/NTVL | T23: Dulux | U23: Dulux (Hoa Sen) | Y23: 23/NTCV/XD 24/NTCV/XD 55/NTCV/XD 67/NTCV/XD | Z23: KT-01 HT-04;05;06;07
B24: Bột trét ngoài | C24: bao 40kg | V24: HĐ:00001727 HĐ:00003109 | W24: HĐ:00001727 HĐ:00003109 | X24: HĐ:00001727 HĐ:00003109
B25: Sơn lót ngoài | C25: thùng 18L | V25: HĐ:00001072 HĐ:00003092 | W25: HĐ:00001072 HĐ:00003092 | X25: HĐ:00001072 HĐ:00003092
B26: Sơn hoàn thiện ngoài | C26: thùng 15L | V26: HĐ:00008756 HĐ:00008756 HĐ:00015566 | W26: HĐ:00008756 HĐ:00008756 HĐ:00015566 | X26: HĐ:00008756 HĐ:00008756 HĐ:00015566
A27: 13 | B27: Sơn giả đá cột khu vực sảnh chờ theo thiết kế | C27: m2 | D27: 7.6136522 | E27: ='KL TONG HOP'!E20 -> 7.6136522 | F27: =IF(E27-D27>0,D27,E27) -> 7.6136522 | G27: 92288 | H27: 139150 | I27: =G27+H27 -> 231438 | J27: =D27*I27 -> 1762088.4 | K27: =E27*I27 -> 1762088.4 | L27: =F27*(G27+H27) -> 1762088.4 | M27: =L27-J27 -> 0 | N27: =L27-K27 -> 0 | O27: Hòa Bình/Kova | P27: Hoa Sen | Q27: Mua từ chuỗi hệ thống HS Home | R27: 03/NTVL | T27: Kova | U27: Kova | V27: BBNT ngày 10/9/2022 | Y27: 68/NTCV/XD | Z27: KT-34
A28: 14 | B28: Láng nền sàn phẳng, vữa Xi măng M75, dày 2cm -5cm | C28: m2 | D28: 1305.4874 | E28: ='KL TONG HOP'!E21 -> #REF! | F28: ='Dien giai KL'!#REF! -> #REF! | G28: 40376 | H28: 54450 | I28: =G28+H28 -> 94826 | J28: =D28*I28 -> 1.2379415e+08 | K28: =E28*I28 -> #REF! | L28: =F28*(G28+H28) -> #REF! | M28: =L28-J28 -> #REF! | N28: =L28-K28 -> #REF! | O28: Xi măng PC40 Fico | P28: Hoa Sen | Q28: Mua từ chuỗi hệ thống HS Home | R28: 02/NTVL | T28: Xi măng PC40 Fico | U28: Xi măng PC40 Fico | Y28: 33/NTCV/XD 35/NTCV/XD 57/NTCV/XD | Z28: KT-09;10;11;12
B29: Cát | C29: m3 | V29: BBNT ngày 28/05/2022 | W29: 180859.CN.PRO.CN22 | X29: 180859.CN.PRO.CN22 | AA29: 16/05-55/KQTN
B30: Xi măng | C30: bao | V30: HĐ:0002169 HĐ:00000223 HĐ:00000439 HĐ:00010569 | W30: HĐ:0002169 HĐ:00000223 HĐ:00000439 HĐ:00010569 | X30: HĐ:0002169 HĐ:00000223 HĐ:00000439 HĐ:00010569
A31: 15 | B31: Láng nền sàn phẳng, vữa Xi măng M75, dày 15mm, tạo dốc về phiễu thu dày 2cm -5cm | C31: m2 | D31: 93.63 | E31: ='KL TONG HOP'!#REF! -> #REF! | F31: =IF(E31-D31>0,D31,E31) -> #REF! | G31: 40376 | H31: 54450 | I31: =G31+H31 -> 94826 | J31: =D31*I31 -> 8878558.4 | K31: =E31*I31 -> #REF! | L31: =F31*(G31+H31) -> #REF! | M31: =L31-J31 -> #REF! | N31: =L31-K31 -> #REF! | O31: Xi măng PC40 Fico | P31: Hoa Sen | Q31: Mua từ chuỗi hệ thống HS Home | R31: 02/NTVL | T31: Xi măng PC40 Fico | U31: Xi măng PC40 Fico | Y31: 33/NTCV/XD 35/NTCV/XD 57/NTCV/XD | Z31: KT-13
B32: Cát | C32: m3 | V32: BBNT ngày 28/05/2022 | W32: 180859.CN.PRO.CN22 | X32: 180859.CN.PRO.CN22 | AA32: 16/05-55/KQTN
B33: Xi măng | C33: bao 50kg | V33: HĐ:0002169 HĐ:00000223 HĐ:00000439 HĐ:00010569 | W33: HĐ:0002169 HĐ:00000223 HĐ:00000439 HĐ:00010569 | X33: HĐ:0002169 HĐ:00000223 HĐ:00000439 HĐ:00010569
A34: 16 | B34: Quét chống thấm khu vực nhà vệ sinh bằng SikaTop Seal107 (Yêu cầu thời gian bảo hành 03 năm). + Theo Quy Trình: - Công tác riêng : Đục tẩy lớp vữa cán hồ đến lớp bê tông sàn hiện hữu , vệ sinh thổi bụi làm sạch. - Quét chống thấm (2 lớp) bằng sika top Seal 107_Lớp 1 - Gia cố chân tường bằng màng polyeste 150mm - (Chống thấm sàn và chân tường cao 300mm) - Trét quét phủ (fill) cổ ống thoát nước bao gồm chống thấm cổ ống - Ngâm nước kiểm tra (test nước) 3 ngày - Cán nền bảo vệ lớp chống thấm - Nâng nền bằng cao độ thiết kế - Cán nền, tạo dốc (theo thiết kế). - Quét chống thấm (2 lớp) bằng sika top Seal 107_Lớp 2 Cán nền - lát gạch hoàn thiện bằng keo. | C34: m2 | D34: 127.56 | E34: ='KL TONG HOP'!#REF! -> #REF! | F34: ='Dien giai KL'!#REF! -> #REF! | G34: 317240 | H34: 169400 | I34: =G34+H34 -> 486640 | J34: =D34*I34 -> 62075798 | K34: =E34*I34 -> #REF! | L34: =F34*(G34+H34) -> #REF! | M34: =L34-J34 -> #REF! | N34: =L34-K34 -> #REF! | Q34: Đồng nhất biện pháp thi công | R34: 14/NTVL | T34: SikaTop Seal107 | U34: SikaTop Seal107 | Y34: 36/NTCV/XD | Z34: KT-13
B35: Sika Top Seal 107 | C35: bộ 25kg | V35: BBNT ngày 16/08/2022 | W35: 12021L36010B | X35: 12021L36010B | AD35: Đinh mức | AE35: 1.5-2kg/m2/lớp | AG35: 1 bộ =20kg bột+5kg nước
B36: Thanh trương nở | C36: cuộn | V36: BBNT ngày 16/08/2022
A37: 17 | B37: Lát gạch nền, sàn bằng gạch Granite màu vàng kem, kích thước 800x800mm. Chà ron bằng keo chà ron Lát gạch bằng keo dán gạch | C37: m2 | D37: 1214.3674 | E37: ='KL TONG HOP'!#REF! -> #REF! | F37: =IF(E37-D37>0,D37,E37) -> #REF! | G37: 315000 | H37: 228690 | I37: =G37+H37 -> 543690 | J37: =D37*I37 -> 6.6023941e+08 | K37: =E37*I37 -> #REF! | L37: =F37*(G37+H37) -> #REF! | M37: =L37-J37 -> #REF! | N37: =L37-K37 -> #REF! | Q37: Mua từ chuỗi hệ thống HS Home | R37: 09/NTVL | U37: Hoa Sen | V37: HĐ:00004137 | W37: HĐ:00004137 | X37: HĐ:00004137 | Y37: 43/NTCV/XD 56/NTCV/XD 63/NTCV/XD | Z37: KT-09;10;11;12
B38: Gạch 800x800 màu vàng kem | C38: m2
A39: B | B39: HẠNG MỤC MEP | D39: 0 | E39: ='KL TONG HOP'!#REF! -> #REF! | J39: =SUBTOTAL(9,J40:J57) -> 2.1080519e+08 | K39: =SUBTOTAL(9,K40:K57) -> #REF! | L39: =SUBTOTAL(9,L40:L57) -> #REF!
A40: I | B40: Hệ thống điện | D40: 0 | E40: ='KL TONG HOP'!#REF! -> #REF!
...

Sheet Bảng kl kèm NTVL
B1: Cộng hòa xã hội chủ nghĩa Việt Nam
B2: Độc lập - tự do - hạnh phúc
B3: -----o0o-----
B6: BẢNG KHỐI LƯỢNG VẬT LIỆU - THIẾT BỊ - SẢN PHẨM NHẬP VỀ CÔNG TRÌNH
C7: ="Dự án: "&'[1]NT-VL hs'!C9 -> Dự án: Văn phòng trụ sở chính - Tập Đoàn Hoa Sen
C8: ="Hạng mục: "&'[1]NT-VL hs'!$C$11 -> Hạng mục: Thi công Xây dựng, M&E
C9: ="Địa điểm: "&'[1]NT-VL hs'!C12 -> Địa điểm: Số 09, Đại Lộ Thống Nhất, KCN Sóng Thần II, P Dĩ An, TP Dĩ An, Bình Dương.
B11: Stt | C11: Tên thiết bị/vật tư | D11: Đ. vị | E11: Khối lượng | F11: Nhãn hiệu | G11: Quy cách | H11: Xuất xứ | I11: Ghi chú | J11: Chứng từ xuất xưởng hoặc CO | L11: CQ | N11: Bảng khối lượng nhập về công trình | O11: Phiếu giao hàng | P11: Kết quả thí nghiệm đối chứng | R11: Hình ảnh tập kết
J12: Gốc, sao y - công chứng | K12: Photo giáp lai công ty | L12: Gốc, sao y - công chứng | M12: Photo giáp lai công ty | P12: Gốc, sao y - công chứng | Q12: Photo giáp lai công ty
A13: Mã VT | B13: A | C13: HẠNG MỤC XÂY DỰNG
C14: NTVL 01
A15: Thép hộp mạ kẽm | B15: 1 | C15: Thép hộp mạ kẽm Z080: 40mmx40mmx1.40mmx6.0m | D15: kg | E15: 151.65 | F15: Hoa sen | G15: 6m/1 cây | H15: Hoa sen | I15: CĐT cấp | N15: x | O15: Hóa đơn VAT
A16: Thép hộp mạ kẽm | B16: 2 | C16: Thép hộp mạ kẽm Z080: 30mmx30mmx1.20mmx6.0m | D16: kg | E16: 155.04 | F16: Hoa sen | G16: 6m/1 cây | H16: Hoa sen | I16: CĐT cấp | N16: x | O16: Hóa đơn VAT
C17: NTVL 02
A18: Gạch 80x80x180mm | B18: 1 | C18: Gạch 80x80x180mm | D18: viên | E18: 10500 | F18: Tuynel | G18: 80x80x180mm | H18: Bình Dương | J18: x | L18: x | N18: x | O18: x | P18: x
A19: Gạch 40x80x180mm | B19: 2 | C19: Gạch 40x80x180mm | D19: viên | E19: 4000 | F19: Tuynel | G19: 40x80x180mm | H19: Bình Dương | J19: x | L19: x | N19: x | O19: x | P19: x
A20: Cát | B20: 3 | C20: Cát xây dựng | D20: m3 | E20: 98.5 | F20: Cát vàng | H20: Bình Dương | J20: x | L20: x | N20: x | O20: x | P20: x
A21: Xi măng | B21: 4 | C21: Xi măng | D21: bao | E21: 500 | F21: FICO | G21: PCB40 | H21: Việt Nam | I21: CĐT cấp | N21: x | O21: Hóa đơn VAT
C22: NTVL 03
A23: Bột trét trong | B23: 1 | C23: Bột trét nội thất KORE INTERIOR KCC: 40kg | D23: bao | E23: 111 | F23: KCC | G23: 40kg/bao | H23: Korea | I23: CĐT cấp | N23: x | O23: Hóa đơn VAT
A24: Bột trét ngoài | B24: 2 | C24: Bột trét tường cao cấp trong nhà và ngoài trời A502-29133 Dulux : 40kg | D24: bao | E24: 40 | F24: Dullux | G24: 40kg/bao | H24: Việt Nam | I24: CĐT cấp | N24: x | O24: Hóa đơn VAT
A25: Sơn lót trong | B25: 3 | C25: Sơn lót nội thất KORE SEALER KCC: 18L | D25: thùng | E25: 20 | F25: KCC | G25: Thùng 18L | H25: Korea | I25: CĐT cấp | N25: x | O25: Hóa đơn VAT
A26: Sơn lót ngoài | B26: 4 | C26: Sơn lót cao cấp ngoài trời WEATHERSHIELD chống kiềm A936-75230 Dulux: 18L | D26: thùng | E26: 10 | F26: Dullux | G26: Thùng 18L | H26: Việt Nam | I26: CĐT cấp | N26: x | O26: Hóa đơn VAT
C27: NTVL 04
A28: Thép D10 | B28: 1 | C28: Thép xây dựng dạng vằn VAS D10 CB500 | D28: kg | E28: 6637 | F28: Hoa Sen | G28: Thép gân | H28: Hoa Sen | I28: CĐT cấp | N28: x | O28: Hóa đơn VAT
B29: 2 | C29: Dây kẽm đen ủ mềm HS 1.0 mm | D29: kg | E29: 50 | F29: Hoa Sen | H29: Hoa Sen | I29: CĐT cấp | N29: x | O29: Hóa đơn VAT
C30: NTVL 05
A31: Bê tông M250 | B31: 1 | C31: Bê tông đá 1x2, M250( nền trệt) | D31: m3 | E31: 46 | F31: HKCONS | G31: Bê tông thương phẩm, đá 1x2, M250 R28, độ sụt 10+/-2 | H31: Bình Dương | J31: x | L31: x | N31: x | O31: x | P31: x
C32: NTVL 06
B33: 1 | C33: Sơn dầu galant màu Platium-5204 UR : 17,500mm | D33: thùng | E33: 7 | F33: Galant | G33: 17.5 lít/ thùng | H33: Việt Nam | I33: CĐT cấp | N33: x | O33: Hóa đơn VAT
B34: 2 | C34: Sơn lót chống rỉ ATM màu Platium grey UR: 17,500ml | D34: thùng | E34: 5 | F34: Galant | G34: 17.5 lít/ thùng | H34: Việt Nam | I34: CĐT cấp | N34: x | O34: Hóa đơn VAT
C35: NTVL 07
A36: Trần sợi khoáng | B36: 1 | C36: Tấm trần sợi khoáng Pin Perf UBR | D36: m2 | E36: 1160.952 | F36: UBR | G36: 610mmx610mmx16mm ( cấp 1220x610x16) | I36: CĐT cấp | N36: x | O36: Hóa đơn VAT
A37: Trần thạch cao chìm | B37: 2 | C37: Tấm thạch cao chống ẩm sơn trắng HVP | D37: m2 | E37: 128.8408 | F37: HVP | G37: 1210mmx605x9mm | I37: CĐT cấp | N37: x | O37: Hóa đơn VAT
B38: 3 | C38: Khung trần nổi ArTEK T3660 rãnh đen HVP: | D38: thanh | E38: 325 | F38: HVP | G38: 3660mmx24mmx32mmx0.27mm | I38: CĐT cấp | N38: x | O38: Hóa đơn VAT
B39: 4 | C39: Khung trần nổi ArTEK T1220 rãnh đen HVP: | D39: thanh | E39: 1725 | F39: HVP | G39: 1220mmx24mmx27mmx0.27mm | I39: CĐT cấp | N39: x | O39: Hóa đơn VAT
B40: 5 | C40: Khung trần nổi TEKO V3600 HVP: | D40: thanh | E40: 244 | F40: HVP | G40: 3600mmx20mmx20mmx0.35mm | I40: CĐT cấp | N40: x | O40: Hóa đơn VAT
B41: 6 | C41: Khung trần nổi ArTEK T610 rãnh đen HVP: | D41: thanh | E41: 1725 | F41: HVP | G41: 610mmx24mmx27mmx0.27mm | I41: CĐT cấp | N41: x | O41: Hóa đơn VAT
A42: Trần thạch cao chìm | B42: 7 | C42: Tấm thạch cao chống võng Sheetrock® Standard UBR: | D42: m2 | E42: 600.281 | F42: UBR | G42: 1210mmx2420mmx9.00mm (SE) | I42: CĐT cấp | N42: x | O42: Hóa đơn VAT
B43: 8 | C43: Khung trần chìm U3 UBR: | D43: thanh | E43: 343 | F43: UBR | G43: 35mmx14mmx4000mmx0.30mm | I43: CĐT cấp | N43: x | O43: Hóa đơn VAT
...

Sheet TK VAT TU Hoa Sen
A1: BẢNG THỐNG KÊ GIÁ TRỊ VẬT TƯ HOA SEN BÁN THƯƠNG MẠI
A2: CÔNG TRÌNH: THI CÔNG NÂNG CẤP VĂN PHÒNG HOA SEN BÌNH DƯƠNG
A3: STT | B3: Tên vật tư | C3: Đơn vị tính | D3: Khối lượng chi tiết | E3: Khối lượng tổng | F3: Đơn giá | G3: Thành tiền | H3: Hóa đơn tham chiếu | I3: Hóa đơn tham chiếu PDF | J3: Ghi chú
A4: I | B4: Thép tròn xây dựng, thép hình
A5: 1 | B5: Thép xây dựng dạng thanh vằn VAS D10 CB500-V | C5: kg | D5: 6637 | E5: =D5 -> 6637 | F5: 17870 | G5: =D5*F5 -> 118603190 | H5: 00003082
A6: 2 | B6: Thép hình I POS: 250mmx125mmx6mmx9mmx12.0m | C6: kg | D6: 4262.4 | E6: =SUM(D6:D8) -> 14742 | F6: 22640 | G6: =D6*F6 -> 96500736 | H6: 00003985
A7: 3 | B7: Thép hình I POS: 200mmx100mmx5.5mmx8mmx12.0m | C7: kg | D7: 8434.8 | F7: 22640 | G7: =D7*F7 -> 1.9096387e+08
A8: 4 | B8: Thép I POS: 200mmx100mmx5.50mmx8.00mmx6.0m | C8: kg | D8: 2044.8 | F8: 23510 | G8: =D8*F8 -> 48073248 | H8: 00007858
A9: I | B9: Thép hộp, thép ống mạ kẽm
A10: 1 | B10: Thép hộp mạ kẽm Z080: 40mmx40mmx1.40mmx6.0m | C10: kg | D10: 151.65 | E10: =D10 -> 151.65 | F10: 27190 | G10: =D10*F10 -> 4123363.5 | H10: 00001971
A11: 2 | B11: Thép hộp mạ kẽm Z080: 30mmx30mmx1.20mmx6.0m | C11: kg | D11: 155.04 | E11: =D11 -> 155.04 | F11: 27190 | G11: =D11*F11 -> 4215537.6
A12: 3 | B12: Thép hộp mạ kẽm Z080: 50mmx100mmx1.40mmx4.0m | C12: kg | D12: 3609.2 | E12: =D12 -> 3609.2 | F12: 23320 | G12: =D12*F12 -> 84166544 | H12: 00005796
A13: 4 | B13: Thép ống mạ kẽm Z080: 49mmx1.10mmx6.0m | C13: kg | D13: 612 | F13: 23320 | G13: =D13*F13 -> 14271840 | H13: 00005797
A14: II | B14: Tole sàn Deck
A15: 1 | B15: Thép dày mạ kẽm Z08 phủ CR: 0.95mmx1200mm TCT SGC 340 00340122020114100 | C15: kg | D15: 4070 | E15: =SUM(D15:D17) -> 4956.1 | F15: 26140 | G15: =D15*F15 -> 106389800 | H15: 00003885
A16: 2 | B16: Thép dày mạ kẽm Z080 phủ CR: 0.95mmx1200mm G350 00340422050053000 | C16: kg | D16: 535.1 | F16: 26140 | G16: =D16*F16 -> 13987514
A17: 3 | B17: Thép dày mạ kẽm Z080 phủ CR: 0.95mmx1200mm G350 00340422050053000 | C17: kg | D17: 351 | F17: 25955 | G17: =D17*F17 -> 9110205
A18: 4 | B18: Tôn lạnh màu trong AF CL AZ100 00/05: 0.50mmx1200mm G550 00350122040070200 | C18: kg | D18: 138.7 | E18: =D18 -> 138.7 | F18: 29275.004 | G18: =D18*F18 -> 4060443
A19: III | B19: Gạch ốp lát, keo dán gạch
A20: 1 | B20: Gạch granite màu kem vân đá hoa cương VB810 VID: 800mmx800mm | C20: m2 | D20: 1424.64 | E20: =D20 -> 1424.64 | F20: 291666.67 | G20: =D20*F20 -> 4.1552001e+08 | H20: 00004137
A21: 2 | B21: Gạch granite màu nâu bóng vân đá hoa cương VB832 VID: 800mmx800mm | C21: m2 | D21: 42.24 | E21: =D21+D24 -> 46.08 | F21: 291666.67 | G21: =D21*F21 -> 12320000
A22: 3 | B22: Gạch granite màu nâu bóng vân đá hoa cương VB632 VID: 600mmx600mm | C22: m2 | D22: 374.4 | E22: =D22+D24+D25 -> 382.56 | F22: 240740.74 | G22: =D22*F22 -> 90133333 | H22: 00004927
A23: 4 | B23: Gạch granite màu nâu nhám vân đá hoa cương V632 VID: 600mmx600mm | C23: m2 | D23: 105.12 | E23: =D23 -> 105.12 | F23: 227777.78 | G23: =D23*F23 -> 23944000 | H23: 00007674
A24: 5 | B24: Gạch granite màu nâu bóng vân đá hoa cương VB832 VID: 800mmx800mm | C24: m2 | D24: 3.84 | F24: 291666.67 | G24: =D24*F24 -> 1120000 | H24: 00014568
A25: 6 | B25: Gạch granite màu nâu bóng vân đá hoa cương VB632 VID: 600mmx600mm | C25: m2 | D25: 4.32 | F25: 240740.74 | G25: =D25*F25 -> 1040000 | H25: 00018342
A26: 7 | B26: Keo (Vữa) dán gạch Cá Sấu Green màu Xám C01010106 CCD: 20kg | C26: gói | D26: 250 | F26: 254545.46 | G26: =D26*F26 -> 63636364 | H26: 00008136
A27: 8 | B27: Keo (Vữa) dán gạch Cá Sấu Green màu Xám C01010106 CCD: 20kg | C27: gói | D27: 50 | F27: 254545.46 | G27: =D27*F27 -> 12727273 | H27: 00008282
A28: 9 | B28: Keo (Vữa) dán gạch Cá Sấu Green màu Xám C01010106 CCD: 20kg | C28: gói | D28: 322 | F28: 254545.45 | G28: =D28*F28 -> 81963636 | H28: 00003399
A29: 10 | B29: Keo (Vữa) dán gạch Cá Sấu Red màu Xám C01920106 CCD: 20kg | C29: gói | D29: 28 | F29: 300000 | G29: =D29*F29 -> 8400000
A30: 11 | B30: Keo (Vữa) chà ron Cá Sấu Silver màu White C02141001 CCD: 1kg | C30: gói | D30: 150 | F30: 25454.547 | G30: =D30*F30 -> 3818182 | H30: 00002946
A31: IV | B31: Sơn nước
A32: 1 | B32: Bột trét nội thất KORE PUTTY INTERIOR KCC: 40KG | C32: bao | D32: 1 | F32: 176400 | G32: =D32*F32 -> 176400 | H32: 0001727
B33: Bột trét nội thất KORE PUTTY INTERIOR KCC: 40KG | C33: bao | D33: 60 | F33: 176400.07 | G33: =D33*F33 -> 10584004 | H33: 0003109
B34: Bột trét nội thất KORE PUTTY INTERIOR KCC: 40KG | C34: bao | D34: 20 | F34: 176500 | G34: =D34*F34 -> 3530000 | H34: 00007823
B35: Bột trét nội thất KORE PUTTY INTERIOR KCC: 40KG | C35: bao | D35: 25 | F35: 176500 | G35: =D35*F35 -> 4412500 | H35: 00012690
B36: Bột trét nội thất KORE PUTTY INTERIOR KCC: 40KG | C36: bao | D36: 5 | F36: 176500 | G36: =D36*F36 -> 882500 | H36: 00014569
A37: 2 | B37: Bột trét ngọai thất KORE PUTTY EXTERIOR KCC: 40KG | C37: bao | D37: 1 | F37: 210000 | G37: =D37*F37 -> 210000 | H37: 0001727
A38: 3 | B38: Bột trét tường cao cấp trong nhà và ngoài trời A502 - 29133 Dulux: 40KG | C38: bao | D38: 35 | F38: 454091.26 | G38: =D38*F38 -> 15893194 | H38: 0003109
A39: 4 | B39: Sơn lót nội thất KORESEALER KCC: 18L | C39: thùng | D39: 20 | F39: 786136.5 | G39: =D39*F39 -> 15722730 | H39: 00001072
A40: 5 | B40: Sơn lót cao cấp ngoài trời WEATHERSHIELD Chống Kiềm A936 - 75230 Dulux: 18L | C40: thùng | D40: 9 | F40: 2414454.2 | G40: =D40*F40 -> 21730088
...

Sheet TONG HOP GT
A1: BẢNG XÁC NHẬN GIÁ TRỊ HOÀN THÀNH
A2: ='PL SOAT XET'!A2:AC2 -> CÔNG TRÌNH : THI CÔNG ………………
A3: ='PL SOAT XET'!A3:AC3 -> ĐỊA ĐIỂM: ………………
A4: ='PL SOAT XET'!A4:AC4 -> SỐ HỢP ĐỒNG: …………………
A5: STT | B5: NỘI DUNG CÔNG VIỆC | C5: ĐVT | D5: KHỐI LƯỢNG | G5: ĐƠN GIÁ | J5: THÀNH TIỀN | M5: MÔ TẢ KỸ THUẬT | N5: HÃNG - XUẤT XỨ | O5: GHI CHÚ
D6: HỢP ĐỒNG+PL | E6: THỰC HIỆN | F6: THANH/QUYẾT TOÁN | G6: VẬT TƯ | H6: NHÂN CÔNG | I6: TỔNG CỘNG | J6: HỢP ĐỒNG+PL | K6: THỰC HIỆN | L6: THANH/QUYẾT TOÁN
A7: A | B7: HẠNG MỤC XÂY DỰNG | J7: =SUBTOTAL(9,J8:J18) -> 7.4014659e+08 | K7: =SUBTOTAL(9,K8:K18) -> #REF! | L7: =SUBTOTAL(9,L8:L18) -> #REF!
A8: 1 | B8: Chi phí Điện - Nước thi công | C8: gói | D8: 1 | E8: ='KL TONG HOP'!E8 -> 1 | F8: =MIN(E8,D8) -> 1 | G8: 0 | H8: 0 | I8: =G8+H8 -> 0 | J8: =D8*I8 -> 0 | K8: =E8*I8 -> 0 | L8: =F8*(G8+H8) -> 0 | O8: Giá đã bao gồm chi phí điện nước phục vụ thi công
A9: 2 | B9: Chi phí xin giấy phép xây dựng | C9: gói | D9: 1 | E9: ='KL TONG HOP'!E9 -> 1 | F9: =MIN(E9,D9) -> 1 | G9: 0 | H9: 12100000 | I9: =G9+H9 -> 12100000 | J9: =D9*I9 -> 12100000 | K9: =E9*I9 -> 12100000 | L9: =F9*(G9+H9) -> 12100000
A10: 3 | B10: Tháo dỡ theo bản vẽ thiết kế được duyệt và theo yêu cầu của CĐT trong quá trình triển khai thi công,.... | C10: trọn gói | D10: 1 | E10: ='KL TONG HOP'!E10 -> 1 | F10: =MIN(E10,D10) -> 1 | G10: 0 | H10: 60500000 | I10: =G10+H10 -> 60500000 | J10: =D10*I10 -> 60500000 | K10: =E10*I10 -> 60500000 | L10: =F10*(G10+H10) -> 60500000
A11: 4 | B11: Vận chuyển rác thải, xà bần ra ngoài công trình | C11: gói | D11: 1 | E11: ='KL TONG HOP'!E11 -> 1 | F11: =MIN(E11,D11) -> 1 | G11: 0 | H11: 36300000 | I11: =G11+H11 -> 36300000 | J11: =D11*I11 -> 36300000 | K11: =E11*I11 -> 36300000 | L11: =F11*(G11+H11) -> 36300000
A12: 5 | B12: Cạo, xủi vệ sinh lớp sơn tường cũ trong nhà | C12: m2 | D12: 1852.2149 | E12: ='KL TONG HOP'!E12 -> 1852.2149 | F12: =MIN(E12,D12) -> 1852.2149 | G12: 0 | H12: 24200 | I12: =G12+H12 -> 24200 | J12: =D12*I12 -> 44823601 | K12: =E12*I12 -> 44823601 | L12: =F12*(G12+H12) -> 44823601
A13: 6 | B13: Cạo, xủi vệ sinh lớp sơn tường cũ ngoài nhà | C13: m2 | D13: 1541.9158 | E13: ='KL TONG HOP'!E13 -> 1541.9158 | F13: =MIN(E13,D13) -> 1541.9158 | G13: 0 | H13: 36300 | I13: =G13+H13 -> 36300 | J13: =D13*I13 -> 55971543 | K13: =E13*I13 -> 55971543 | L13: =F13*(G13+H13) -> 55971543
A14: 7 | B14: Vệ sinh nền sảnh trệt, cầu thang và đánh bóng lại đá lát nền hiện trạng | C14: gói | D14: 1 | E14: ='KL TONG HOP'!E14 -> 1 | F14: =MIN(E14,D14) -> 1 | G14: 0 | H14: 12100000 | I14: =G14+H14 -> 12100000 | J14: =D14*I14 -> 12100000 | K14: =E14*I14 -> 12100000 | L14: =F14*(G14+H14) -> 12100000
A15: 8 | B15: Vệ sinh và sơn PU tay vịn lan can cầu thang | C15: gói | D15: 1 | E15: ='KL TONG HOP'!E15 -> 1 | F15: =MIN(E15,D15) -> 1 | G15: 0 | H15: 36300000 | I15: =G15+H15 -> 36300000 | J15: =D15*I15 -> 36300000 | K15: =E15*I15 -> 36300000 | L15: =F15*(G15+H15) -> 36300000
A16: 9 | B16: Đục phá lớp gạch lát sàn, vữa lót nền tới lớp bê tông sàn hiện hữu (xử lý trước khi láng nền sàn) | C16: m2 | D16: 2211.2774 | E16: ='KL TONG HOP'!E16 -> 2211.2774 | F16: =MIN(E16,D16) -> 2211.2774 | G16: 0 | H16: 60500 | I16: =G16+H16 -> 60500 | J16: =D16*I16 -> 1.3378228e+08 | K16: =E16*I16 -> 1.3378228e+08 | L16: =F16*(G16+H16) -> 1.3378228e+08
A17: 10 | B17: Tháo dỡ cầu thang hiện hữu tầng 1, tầng 2, hoàn thiện mặt nền tới cao độ hiện trạng (Bao gồm Bê tông, ván khuôn, khoan cấy thép, cán nền, …) | C17: gói | D17: 1 | E17: ='KL TONG HOP'!E17 -> 1 | F17: =MIN(E17,D17) -> 1 | G17: 0 | H17: 19360000 | I17: =G17+H17 -> 19360000 | J17: =D17*I17 -> 19360000 | K17: =E17*I17 -> 19360000 | L17: =F17*(G17+H17) -> 19360000
A18: 11 | B18: Sơn dầm, trần, cột, tường trong nhà (bã mastic 02 lớp, sơn 01 lớp lót 02 lớp hoàn thiện) | C18: m2 | D18: 2641.5861 | E18: ='KL TONG HOP'!E18 -> #REF! | F18: =MIN(E18,D18) -> #REF! | G18: 51912 | H18: 72600 | I18: =G18+H18 -> 124512 | J18: =D18*I18 -> 3.2890916e+08 | K18: =E18*I18 -> #REF! | L18: =F18*(G18+H18) -> #REF! | M18: Dulux | N18: Hoa Sen | O18: Mua từ chuỗi hệ thống HS Home
B19: TỔNG CỘNG (Chưa bao gồm VAT) | J19: =SUBTOTAL(9,J7:J18) -> 7.4014659e+08 | K19: =SUBTOTAL(9,K7:K18) -> #REF! | L19: =SUBTOTAL(9,L7:L18) -> #REF!
B20: THUẾ VAT 8% | J20: =J19*0.08 -> 59211727 | K20: =K19*0.08 -> #REF! | L20: =L19*0.08 -> #REF!
B21: TỔNG CỘNG (Bao gồm VAT 8%)
B22: Ghi chú:
K23: ……, ngày……tháng……năm 2023
B24: ĐẠI DIỆN NHÀ THẦU THI CÔNG | K24: ĐẠI DIỆN CHỦ ĐẦU TƯ

Sheet KL TONG HOP
A1: BẢNG TỔNG HỢP KHỐI LƯỢNG
A2: ='TONG HOP GT'!A2:O2 -> CÔNG TRÌNH : THI CÔNG ………………
A3: ='TONG HOP GT'!A3:O3 -> ĐỊA ĐIỂM: ………………
A4: ='TONG HOP GT'!A4:O4 -> SỐ HỢP ĐỒNG: …………………
A5: STT | B5: NỘI DUNG CÔNG VIỆC | C5: ĐVT | D5: KHỐI LƯỢNG HỢP ĐỒNG+PL | E5: KHỐI LƯỢNG THỰC HIỆN | F5: TỶ LỆ HOÀN THÀNH SO VỚI HĐ+PL(%) | G5: GHI CHÚ
A7: A | B7: HẠNG MỤC XÂY DỰNG
A8: 1 | B8: Chi phí Điện - Nước thi công | C8: gói | D8: 1 | E8: ='Dien giai KL'!J8 -> 1 | F8: =E8/D8 -> 1
A9: 2 | B9: Chi phí xin giấy phép xây dựng | C9: gói | D9: 1 | E9: ='Dien giai KL'!J9 -> 1 | F9: =E9/D9 -> 1
A10: 3 | B10: Tháo dỡ theo bản vẽ thiết kế được duyệt và theo yêu cầu của CĐT trong quá trình triển khai thi công,.... | C10: trọn gói | D10: 1 | E10: ='Dien giai KL'!J10 -> 1 | F10: =E10/D10 -> 1
A11: 4 | B11: Vận chuyển rác thải, xà bần ra ngoài công trình | C11: gói | D11: 1 | E11: ='Dien giai KL'!J11 -> 1 | F11: =E11/D11 -> 1
A12: 5 | B12: Cạo, xủi vệ sinh lớp sơn tường cũ trong nhà | C12: m2 | D12: 1852.2149 | E12: ='Dien giai KL'!J12 -> 1852.2149 | F12: =E12/D12 -> 1
A13: 6 | B13: Cạo, xủi vệ sinh lớp sơn tường cũ ngoài nhà | C13: m2 | D13: 1541.9158 | E13: ='Dien giai KL'!J146 -> 1541.9158 | F13: =E13/D13 -> 1
A14: 7 | B14: Vệ sinh nền sảnh trệt, cầu thang và đánh bóng lại đá lát nền hiện trạng | C14: gói | D14: 1 | E14: ='Dien giai KL'!J257 -> 1 | F14: =E14/D14 -> 1
A15: 8 | B15: Vệ sinh và sơn PU tay vịn lan can cầu thang | C15: gói | D15: 1 | E15: ='Dien giai KL'!J258 -> 1 | F15: =E15/D15 -> 1
A16: 9 | B16: Đục phá lớp gạch lát sàn, vữa lót nền tới lớp bê tông sàn hiện hữu (xử lý trước khi láng nền sàn) | C16: m2 | D16: 2211.2774 | E16: ='Dien giai KL'!J259 -> 2211.2774 | F16: =E16/D16 -> 1
A17: 10 | B17: Tháo dỡ cầu thang hiện hữu tầng 1, tầng 2, hoàn thiện mặt nền tới cao độ hiện trạng (Bao gồm Bê tông, ván khuôn, khoan cấy thép, cán nền, …) | C17: gói | D17: 1 | E17: ='Dien giai KL'!J327 -> 1 | F17: =E17/D17 -> 1
A18: 11 | B18: Sơn dầm, trần, cột, tường trong nhà (bã mastic 02 lớp, sơn 01 lớp lót 02 lớp hoàn thiện) | C18: m2 | D18: 2641.5861 | E18: ='Dien giai KL'!J328 -> #REF! | F18: =E18/D18 -> #REF!
A19: 12 | B19: Sơn dầm, trần, cột, tường ngoài nhà (bã mastic 02 lớp, sơn 01 lớp lót 02 lớp hoàn thiện) | C19: m2 | D19: 1541.9158 | E19: ='Dien giai KL'!J347 -> 1541.9158 | F19: =E19/D19 -> 1
A20: 13 | B20: Sơn giả đá cột khu vực sảnh chờ theo thiết kế | C20: m2 | D20: 7.6136522 | E20: ='Dien giai KL'!J348 -> 7.6136522 | F20: =E20/D20 -> 1
A21: 14 | B21: Láng nền sàn phẳng, vữa Xi măng M75, dày 2cm -5cm | C21: m2 | D21: 1305.4874 | E21: ='Dien giai KL'!#REF! -> #REF! | F21: =E21/D21 -> #REF!
F23: ……, ngày……tháng……năm 2023
B24: ĐẠI DIỆN NHÀ THẦU THI CÔNG | F24: ĐẠI DIỆN CHỦ ĐẦU TƯ

Sheet Dien giai KL
A1: BẢNG DIỄN GIẢI KHỐI LƯỢNG
A2: ='TONG HOP GT'!A2:O2 -> CÔNG TRÌNH : THI CÔNG ………………
A3: ='TONG HOP GT'!A3:O3 -> ĐỊA ĐIỂM: ………………
A4: ='TONG HOP GT'!A4:O4 -> SỐ HỢP ĐỒNG: …………………
A5: STT | B5: NỘI DUNG CÔNG VIỆC | C5: ĐVT | D5: KÍCH THƯỚC | G5: SỐ LƯỢNG | H5: HỆ SỐ | I5: KHỐI LƯỢNG THỰC HIỆN | K5: GHI CHÚ
D6: DÀI | E6: RỘNG | F6: CAO | I6: TỪNG PHẦN | J6: TỔNG
A7: A | B7: HẠNG MỤC XÂY DỰNG
A8: 1 | B8: Chi phí Điện - Nước thi công | C8: gói | J8: 1
A9: =+A8+1 -> 2 | B9: Chi phí xin giấy phép xây dựng | C9: gói | J9: 1
A10: =+A9+1 -> 3 | B10: Tháo dỡ theo bản vẽ thiết kế được duyệt và theo yêu cầu của CĐT trong quá trình triển khai thi công,.... | C10: trọn gói | J10: 1
A11: =+A10+1 -> 4 | B11: Vận chuyển rác thải, xà bần ra ngoài công trình | C11: gói | J11: 1
A12: =+A11+1 -> 5 | B12: Cạo, xủi vệ sinh lớp sơn tường cũ trong nhà | C12: m2 | J12: =SUM(I13:I145) -> 1852.2149
B13: 1. Tầng trệt
B14: Tường trong phòng: trục A-B/1-2 | D14: =5.85+4.8+3+0.45 -> 14.1 | F14: 3 | G14: 1 | H14: 1 | I14: =PRODUCT(D14:H14) -> 42.3 | K14: KT-01; KT-18 | L14: Cao độ trần 3m
B15: Trừ cửa sổ W2 trục 1/A-A' | D15: 2 | F15: 1.7 | G15: 1 | H15: -1 | I15: =PRODUCT(D15:H15) -> -3.4 | K15: HT-06
B16: Trừ vách kính tường biên trục A/1-2 | D16: 1.65 | F16: 2.9 | G16: 1 | H16: -1 | I16: =PRODUCT(D16:H16) -> -4.785 | K16: HT-05
B17: Tường trong phòng: trục A-B/7-8 | D17: =6.05+4.9+0.88 -> 11.83 | F17: 3 | G17: 1 | H17: 1 | I17: =PRODUCT(D17:H17) -> 35.49 | K17: KT-01; KT-18 | L17: Cao độ trần 3m
B18: Trừ cửa sổ W1 trục 8/A-A' | D18: 2.4 | F18: 1.7 | G18: 1 | H18: -1 | I18: =PRODUCT(D18:H18) -> -4.08 | K18: HT-06
B19: Trừ vách kính tường biên trục A/7-8 | D19: 1.65 | F19: 2.9 | G19: 1 | H19: -1 | I19: =PRODUCT(D19:H19) -> -4.785 | K19: HT-05
B20: Tường trong phòng: trục B-B'/3-4 | D20: =(5.9+4.9)*2 -> 21.6 | F20: 3 | G20: 1 | H20: 1 | I20: =PRODUCT(D20:H20) -> 64.8 | K20: KT-01; KT-18 | L20: Cao độ trần 3m
B21: Trừ cửa sổ W1 trục B/3-4 | D21: 2.4 | F21: 1.7 | G21: 1 | H21: -1 | I21: =PRODUCT(D21:H21) -> -4.08 | K21: HT-07
B22: Trừ vách kính CT3 (trục B'/3-4) | D22: =3.05+0.9 -> 3.95 | F22: =2.4+0.6 -> 3 | G22: 1 | H22: -1 | I22: =PRODUCT(D22:H22) -> -11.85 | K22: KT-25
B23: Tường trong phòng: trục B-B'/5-8 | D23: =5.8*2+4.9*2+4.7+1+0.88+0.2*4+0.3*4+0.4*4 -> 31.58 | F23: 3 | G23: 1 | H23: 1 | I23: =PRODUCT(D23:H23) -> 94.74 | K23: KT-01; KT-18 | L23: Cao độ trần 3m
B24: Trừ cửa sổ W1 trục 8/B-B' | D24: 2.4 | F24: 1.7 | G24: 1 | H24: -1 | I24: =PRODUCT(D24:H24) -> -4.08 | K24: HT-06
B25: Trừ cửa sổ W1 trục B/5-8 | D25: 2.4 | F25: 1.7 | G25: 3 | H25: -1 | I25: =PRODUCT(D25:H25) -> -12.24 | K25: HT-07
B26: Tường trục 4/A-A' (2 mặt) | D26: 5.62 | F26: 3.3 | G26: 1 | H26: 2 | I26: =PRODUCT(D26:H26) -> 37.092 | K26: KT-01;KT-14;KT-18 | L26: Cao độ trần 3.3m
B27: Tường trục 5/A-A' (2 mặt) | D27: 5.62 | F27: 3.3 | G27: 1 | H27: 2 | I27: =PRODUCT(D27:H27) -> 37.092 | K27: KT-01;KT-14;KT-19
B28: Tường ô cầu thang thoát hiểm: trục 1-2/B-B' | D28: =(5.9+2.8)*2 -> 17.4 | F28: =4.15-0.15 -> 4 | G28: 1 | H28: 1 | I28: =PRODUCT(D28:H28) -> 69.6 | K28: KT-01 | L28: Chiều cao bằng cao độ tầng trệt trừ sàn chiếu nghỉ
B29: Đáy cầu thang nhịp 1 | D29: 4.25 | E29: =2.8/2 -> 1.4 | G29: 1 | H29: 1 | I29: =PRODUCT(D29:H29) -> 5.95
B30: Đáy cầu thang nhịp 2 | D30: 3.5 | E30: =2.8/2 -> 1.4 | G30: 1 | H30: 1 | I30: =PRODUCT(D30:H30) -> 4.9
B31: Đáy cầu thang chiếu nghỉ, chiếu tới | D31: 2.8 | E31: 1.6 | G31: 2 | H31: 1 | I31: =PRODUCT(D31:H31) -> 8.96
B32: Trừ cửa đi thoát hiểm | D32: 1.77 | F32: 2.45 | G32: 1 | H32: -1 | I32: =PRODUCT(D32:H32) -> -4.3365
B33: Trừ cửa sổ | D33: 0.6 | F33: 0.45 | G33: 2 | H33: -1 | I33: =PRODUCT(D33:H33) -> -0.54 | K33: HT-07
B34: Tường ô cầu thang giữa: trục 3-4/B-B' | D34: =5.9*2+5.7 -> 17.5 | F34: =4.15-0.15 -> 4 | G34: 1 | H34: 1 | I34: =PRODUCT(D34:H34) -> 70 | K34: KT-01
B35: Đáy cầu thang nhịp 1 | D35: 3.55 | E35: 1.3 | G35: 2 | H35: 1 | I35: =PRODUCT(D35:H35) -> 9.23
B36: Đáy cầu thang nhịp 2 | D36: 3.55 | E36: 2.5 | G36: 1 | H36: 1 | I36: =PRODUCT(D36:H36) -> 8.875
B37: Đáy cầu thang chiếu nghỉ | D37: 5.7 | E37: 1.69 | G37: 1 | H37: 1 | I37: =PRODUCT(D37:H37) -> 9.633
B38: Trừ cửa sổ | D38: 0.6 | F38: 0.45 | G38: 2 | H38: -1 | I38: =PRODUCT(D38:H38) -> -0.54 | K38: HT-07
B39: Tường trong phòng kỹ thuật: trục 2-3/B-B' | D39: =(3.7+2)*2 -> 11.4 | F39: 3.3 | G39: 1 | H39: 1 | I39: =PRODUCT(D39:H39) -> 37.62 | K39: KT-01;KT-14
B40: Trừ cửa đi | D40: 0.9 | F40: 2.2 | G40: 1 | H40: -1 | I40: =PRODUCT(D40:H40) -> -1.98
...

Sheet TK THÉP SÀN
A1: BẢNG THỐNG KÊ CỐT THÉP MÓNG, ĐÀ KIỀNG, CỔ CỘT, SÀN
A2: ='Dien giai KL'!A2:K2 -> CÔNG TRÌNH : THI CÔNG ………………
A3: ='Dien giai KL'!A3:K3 -> ĐỊA ĐIỂM: ………………
A4: ='Dien giai KL'!A4:K4 -> SỐ HỢP ĐỒNG: …………………
A5: Tên cấu kiện | B5: Số hiệu thép | C5: Hình dạng và kích thước | H5: Đường kính | I5: Chiều dài thanh (mm) | J5: Số mối nối | K5: Số lượng | N5: Tổng chiều dài (m) | O5: Tỷ trọng (kg/md) | P5: Tổng khối lượng (kg)
K6: Thanh trên 1CK | L6: Cấu kiện | M6: Toàn bộ
A7: I. THÉP SÀN TẦNG TRỆT | P7: =SUBTOTAL(9,P8:P27) -> 2836.148 | Q7: Bản vẽ KC-22
B8: 1 | E8: 9200 | H8: 10 | I8: =+SUM(C8:G8) -> 9200 | K8: 5 | L8: 1 | M8: =+K8*L8 -> 5 | N8: =+(I8+30*J8*H8)*M8/1000 -> 46 | O8: =(7850*PI()*(H8/1000)^2)/4 -> 0.61653756 | P8: =N8*O8 -> 28.360728
B9: 2 | E9: 9200 | H9: 10 | I9: =+SUM(C9:G9) -> 9200 | K9: 5 | L9: 1 | M9: =+K9*L9 -> 5 | N9: =+(I9+30*J9*H9)*M9/1000 -> 46 | O9: =(7850*PI()*(H9/1000)^2)/4 -> 0.61653756 | P9: =N9*O9 -> 28.360728
B10: 3 | E10: 14050 | H10: 10 | I10: =+SUM(C10:G10) -> 14050 | J10: 1 | K10: 29 | L10: 1 | M10: =+K10*L10 -> 29 | N10: =+(I10+30*J10*H10)*M10/1000 -> 416.15 | O10: =(7850*PI()*(H10/1000)^2)/4 -> 0.61653756 | P10: =N10*O10 -> 256.5721
B11: 4 | E11: 14150 | H11: 10 | I11: =+SUM(C11:G11) -> 14150 | J11: 1 | K11: 28 | L11: 1 | M11: =+K11*L11 -> 28 | N11: =+(I11+30*J11*H11)*M11/1000 -> 404.6 | O11: =(7850*PI()*(H11/1000)^2)/4 -> 0.61653756 | P11: =N11*O11 -> 249.4511
B12: 5 | E12: 13700 | H12: 10 | I12: =+SUM(C12:G12) -> 13700 | J12: 1 | K12: 11 | L12: 1 | M12: =+K12*L12 -> 11 | N12: =+(I12+30*J12*H12)*M12/1000 -> 154 | O12: =(7850*PI()*(H12/1000)^2)/4 -> 0.61653756 | P12: =N12*O12 -> 94.946784
B13: 6 | E13: 13850 | H13: 10 | I13: =+SUM(C13:G13) -> 13850 | J13: 1 | K13: 11 | L13: 1 | M13: =+K13*L13 -> 11 | N13: =+(I13+30*J13*H13)*M13/1000 -> 155.65 | O13: =(7850*PI()*(H13/1000)^2)/4 -> 0.61653756 | P13: =N13*O13 -> 95.964071
B14: 7 | E14: 2800 | H14: 10 | I14: =+SUM(C14:G14) -> 2800 | K14: 30 | L14: 1 | M14: =+K14*L14 -> 30 | N14: =+(I14+30*J14*H14)*M14/1000 -> 84 | O14: =(7850*PI()*(H14/1000)^2)/4 -> 0.61653756 | P14: =N14*O14 -> 51.789155
B15: 8 | E15: 7100 | H15: 10 | I15: =+SUM(C15:G15) -> 7100 | K15: 30 | L15: 1 | M15: =+K15*L15 -> 30 | N15: =+(I15+30*J15*H15)*M15/1000 -> 213 | O15: =(7850*PI()*(H15/1000)^2)/4 -> 0.61653756 | P15: =N15*O15 -> 131.3225
B16: 9 | E16: 4900 | H16: 10 | I16: =+SUM(C16:G16) -> 4900 | K16: 30 | L16: 1 | M16: =+K16*L16 -> 30 | N16: =+(I16+30*J16*H16)*M16/1000 -> 147 | O16: =(7850*PI()*(H16/1000)^2)/4 -> 0.61653756 | P16: =N16*O16 -> 90.631021
B17: 10 | E17: 5700 | H17: 10 | I17: =+SUM(C17:G17) -> 5700 | K17: 30 | L17: 1 | M17: =+K17*L17 -> 30 | N17: =+(I17+30*J17*H17)*M17/1000 -> 171 | O17: =(7850*PI()*(H17/1000)^2)/4 -> 0.61653756 | P17: =N17*O17 -> 105.42792
B18: 11 | E18: 10050 | H18: 10 | I18: =+SUM(C18:G18) -> 10050 | K18: 30 | L18: 1 | M18: =+K18*L18 -> 30 | N18: =+(I18+30*J18*H18)*M18/1000 -> 301.5 | O18: =(7850*PI()*(H18/1000)^2)/4 -> 0.61653756 | P18: =N18*O18 -> 185.88607
B19: 12 | E19: 5950 | H19: 10 | I19: =+SUM(C19:G19) -> 5950 | K19: 15 | L19: 1 | M19: =+K19*L19 -> 15 | N19: =+(I19+30*J19*H19)*M19/1000 -> 89.25 | O19: =(7850*PI()*(H19/1000)^2)/4 -> 0.61653756 | P19: =N19*O19 -> 55.025977
B20: 13 | E20: 7750 | H20: 10 | I20: =+SUM(C20:G20) -> 7750 | K20: 14 | L20: 1 | M20: =+K20*L20 -> 14 | N20: =+(I20+30*J20*H20)*M20/1000 -> 108.5 | O20: =(7850*PI()*(H20/1000)^2)/4 -> 0.61653756 | P20: =N20*O20 -> 66.894325
B21: 14 | E21: 8700 | H21: 10 | I21: =+SUM(C21:G21) -> 8700 | K21: 35 | L21: 1 | M21: =+K21*L21 -> 35 | N21: =+(I21+30*J21*H21)*M21/1000 -> 304.5 | O21: =(7850*PI()*(H21/1000)^2)/4 -> 0.61653756 | P21: =N21*O21 -> 187.73569
B22: 15 | E22: 5900 | H22: 10 | I22: =+SUM(C22:G22) -> 5900 | K22: 36 | L22: 1 | M22: =+K22*L22 -> 36 | N22: =+(I22+30*J22*H22)*M22/1000 -> 212.4 | O22: =(7850*PI()*(H22/1000)^2)/4 -> 0.61653756 | P22: =N22*O22 -> 130.95258
B23: 16 | E23: 14600 | H23: 10 | I23: =+SUM(C23:G23) -> 14600 | J23: 1 | K23: 25 | L23: 1 | M23: =+K23*L23 -> 25 | N23: =+(I23+30*J23*H23)*M23/1000 -> 372.5 | O23: =(7850*PI()*(H23/1000)^2)/4 -> 0.61653756 | P23: =N23*O23 -> 229.66024
B24: 17 | E24: 5308 | H24: 10 | I24: =+SUM(C24:G24) -> 5308 | K24: 29 | L24: 1 | M24: =+K24*L24 -> 29 | N24: =+(I24+30*J24*H24)*M24/1000 -> 153.932 | O24: =(7850*PI()*(H24/1000)^2)/4 -> 0.61653756 | P24: =N24*O24 -> 94.904859
B25: 18 | E25: 14600 | H25: 10 | I25: =+SUM(C25:G25) -> 14600 | J25: 1 | K25: 50 | L25: 1 | M25: =+K25*L25 -> 50 | N25: =+(I25+30*J25*H25)*M25/1000 -> 745 | O25: =(7850*PI()*(H25/1000)^2)/4 -> 0.61653756 | P25: =N25*O25 -> 459.32048
B26: 19 | E26: 13800 | H26: 10 | I26: =+SUM(C26:G26) -> 13800 | J26: 1 | K26: 25 | L26: 1 | M26: =+K26*L26 -> 25 | N26: =+(I26+30*J26*H26)*M26/1000 -> 352.5 | O26: =(7850*PI()*(H26/1000)^2)/4 -> 0.61653756 | P26: =N26*O26 -> 217.32949
B27: Thép tăng cường chân cột | E27: 1460 | H27: 10 | I27: =+SUM(C27:G27) -> 1460 | K27: =2*6+4*6+8*6 -> 84 | L27: 1 | M27: =+K27*L27 -> 84 | N27: =+(I27+30*J27*H27)*M27/1000 -> 122.64 | O27: =(7850*PI()*(H27/1000)^2)/4 -> 0.61653756 | P27: =N27*O27 -> 75.612166
A28: II. THÉP SÀN TẦNG MÁI | P28: =SUBTOTAL(9,P29:P45) -> 3615.9188 | Q28: Bản vẽ KC-23
B29: 1 | E29: 11219 | H29: 10 | I29: =+SUM(C29:G29) -> 11219 | K29: 5 | L29: 1 | M29: =+K29*L29 -> 5 | N29: =+(I29+30*J29*H29)*M29/1000 -> 56.095 | O29: =(7850*PI()*(H29/1000)^2)/4 -> 0.61653756 | P29: =N29*O29 -> 34.584674
B30: 2 | E30: 11217 | H30: 10 | I30: =+SUM(C30:G30) -> 11217 | K30: 5 | L30: 1 | M30: =+K30*L30 -> 5 | N30: =+(I30+30*J30*H30)*M30/1000 -> 56.085 | O30: =(7850*PI()*(H30/1000)^2)/4 -> 0.61653756 | P30: =N30*O30 -> 34.578509
B31: 3 | E31: 11653 | H31: 10 | I31: =+SUM(C31:G31) -> 11653 | J31: 1 | K31: 5 | L31: 1 | M31: =+K31*L31 -> 5 | N31: =+(I31+30*J31*H31)*M31/1000 -> 59.765 | O31: =(7850*PI()*(H31/1000)^2)/4 -> 0.61653756 | P31: =N31*O31 -> 36.847367
B32: 4 | E32: 11647 | H32: 10 | I32: =+SUM(C32:G32) -> 11647 | J32: 1 | K32: 5 | L32: 1 | M32: =+K32*L32 -> 5 | N32: =+(I32+30*J32*H32)*M32/1000 -> 59.735 | O32: =(7850*PI()*(H32/1000)^2)/4 -> 0.61653756 | P32: =N32*O32 -> 36.828871
B33: 5 | E33: 36100 | H33: 10 | I33: =+SUM(C33:G33) -> 36100 | J33: 3 | K33: 41 | L33: 1 | M33: =+K33*L33 -> 41 | N33: =+(I33+30*J33*H33)*M33/1000 -> 1517 | O33: =(7850*PI()*(H33/1000)^2)/4 -> 0.61653756 | P33: =N33*O33 -> 935.28748
B34: 6 | E34: 30950 | H34: 10 | I34: =+SUM(C34:G34) -> 30950 | J34: 2 | K34: 30 | L34: 1 | M34: =+K34*L34 -> 30 | N34: =+(I34+30*J34*H34)*M34/1000 -> 946.5 | O34: =(7850*PI()*(H34/1000)^2)/4 -> 0.61653756 | P34: =N34*O34 -> 583.5528
B35: 7 | E35: 30600 | H35: 10 | I35: =+SUM(C35:G35) -> 30600 | J35: 2 | K35: 6 | L35: 1 | M35: =+K35*L35 -> 6 | N35: =+(I35+30*J35*H35)*M35/1000 -> 187.2 | O35: =(7850*PI()*(H35/1000)^2)/4 -> 0.61653756 | P35: =N35*O35 -> 115.41583
B36: 8 | E36: 1800 | H36: 10 | I36: =+SUM(C36:G36) -> 1800 | K36: 18 | L36: 1 | M36: =+K36*L36 -> 18 | N36: =+(I36+30*J36*H36)*M36/1000 -> 32.4 | O36: =(7850*PI()*(H36/1000)^2)/4 -> 0.61653756 | P36: =N36*O36 -> 19.975817
B37: 9 | E37: 900 | H37: 10 | I37: =+SUM(C37:G37) -> 900 | K37: 9 | L37: 1 | M37: =+K37*L37 -> 9 | N37: =+(I37+30*J37*H37)*M37/1000 -> 8.1 | O37: =(7850*PI()*(H37/1000)^2)/4 -> 0.61653756 | P37: =N37*O37 -> 4.9939542
B38: 10 | E38: 900 | H38: 10 | I38: =+SUM(C38:G38) -> 900 | K38: 9 | L38: 1 | M38: =+K38*L38 -> 9 | N38: =+(I38+30*J38*H38)*M38/1000 -> 8.1 | O38: =(7850*PI()*(H38/1000)^2)/4 -> 0.61653756 | P38: =N38*O38 -> 4.9939542
B39: 11 | E39: 1800 | H39: 10 | I39: =+SUM(C39:G39) -> 1800 | K39: 18 | L39: 1 | M39: =+K39*L39 -> 18 | N39: =+(I39+30*J39*H39)*M39/1000 -> 32.4 | O39: =(7850*PI()*(H39/1000)^2)/4 -> 0.61653756 | P39: =N39*O39 -> 19.975817
B40: 12 | E40: 7900 | H40: 10 | I40: =+SUM(C40:G40) -> 7900 | K40: 26 | L40: 1 | M40: =+K40*L40 -> 26 | N40: =+(I40+30*J40*H40)*M40/1000 -> 205.4 | O40: =(7850*PI()*(H40/1000)^2)/4 -> 0.61653756 | P40: =N40*O40 -> 126.63681
...

Sheet Cable Nguon
A2: BẢNG DIỄN GIẢI CÁP ĐIỆN NGUỒN NGOÀI NHÀ
A3: ='TK THÉP SÀN'!A2:P2 -> CÔNG TRÌNH : THI CÔNG ………………
A4: ='TK THÉP SÀN'!A3:P3 -> ĐỊA ĐIỂM: ………………
A5: ='TK THÉP SÀN'!A4:P4 -> SỐ HỢP ĐỒNG: …………………
E7: Chiều cao tầng 1 | I7: 4.15 | J7: Chiều cao trần tầng 1 | L7: 3.3
E8: Chiều cao tầng 2, 3 | I8: 3.65 | J8: Chiều cao trần tầng 2, 3 | L8: 3.2
E9: Chiều cao Trunking điện Tầng 1 | I9: 3.5 | J9: Chiều cao tủ DB-T1 | L9: 2
E10: Chiều cao Trunking điện Tầng 2, 3 | I10: 3.3 | J10: Chiều cao tủ DB-T2, T3 | L10: 1.5
E11: Chiều cao tủ bơm, XLNT xuống sàn | I11: 2 | J11: Chiều cao điểm đấu nối từ tủ Trạm xuống sàn | L11: 0.5
A12: STT | B12: TÊN LINE | C12: KÍ HIỆU BẢN VẼ | D12: TỪ TRUNKING XUỐNG TỦ DB-T1 | E12: TỪ TỦ TẢI/ XUỐNG SÀN HOẶC LÊN TRẦN | F12: MẶT BẰNG DÂY ĐIỆN ĐI NỔI TRÊN TRẦN/ TRUNKING | G12: MẶT BẰNG DÂY ĐIỆN ĐI ÂM ĐẤT | H12: SỐ LƯỢNG DÂY | I12: DÂY CHỜ ĐẤU NỐI | J12: TỔNG DÂY | K12: HỆ SỐ HAO HỤT | L12: TỔNG CỘNG SAU HAO HỤT
A16: I | B16: TỔNG DÂY Cu/XLPE/PVC 240mm2 | J16: =J17 -> 267.348 | K16: =K17 -> 0 | L16: =SUM(J16:K16) -> 267.348
A17: 1 | B17: Từ Trạm biến áp -> DB-T1 | C17: MEP-OD-01 | D17: =$I$9 -> 3.5 | E17: =$L$11 -> 0.5 | F17: =1.206+1.36+1.32+23.703+6.531+4.7+1 -> 39.82 | G17: =2.604+6.57+0.5+3.143+3+5.1+1.1 -> 22.017 | H17: 4 | I17: 0.5 | J17: =(SUM(D17:G17)*H17)+(I17*2*H17) -> 267.348
A18: II | B18: TỔNG DÂY Cu/PVC 120mm2 | J18: =J19 -> 66.837 | K18: =K19 -> 0 | L18: =SUM(J18:K18) -> 66.837
A19: 1 | B19: Từ Trạm biến áp -> DB-T1 | C19: MEP-OD-01 | D19: =$I$9 -> 3.5 | E19: =$L$11 -> 0.5 | F19: =1.206+1.36+1.32+23.703+6.531+4.7+1 -> 39.82 | G19: =2.604+6.57+0.5+3.143+3+5.1+1.1 -> 22.017 | H19: 1 | I19: 0.5 | J19: =SUM(D19:G19)*H19+I19*2*H19 -> 66.837
A20: III | B20: Ống điện HDPE D130/100 | J20: =J21 -> 38.175 | K20: =K21 -> 0 | L20: =SUM(J20:K20) -> 38.175
A21: 1 | B21: Từ Trạm biến áp -> DB-T1 | C21: MEP-OD-01 | G21: =(5.716*2+3.143+5.1)+(6.8+11)+0.7 -> 38.175 | H21: 1 | J21: =SUM(D21:G21)*H21+I21*2*H21 -> 38.175
A22: IV | B22: TỔNG DÂY Cu/XLPE/PVC 70mm2 | J22: =SUM(J23:J24) -> 89.024 | L22: =SUM(J22:K22) -> 89.024
A23: 1 | B23: Từ tủ DB-T1 -> DB-AC | C23: MEP-PW-01,04 | D23: =$I$9 -> 3.5 | E23: =1.4 -> 1.4 | F23: =(1.23+1.753+0.268)+5 -> 8.251 | H23: 4 | I23: 0.5 | J23: =SUM(D23:G23)*H23+0.2*2*H23 -> 54.204
B24: Trục đứng đi trong thang, máng cáp | C24: MEP-PW-05 | F24: =0.6+0.15+3.65*2+0.655 -> 8.705 | H24: 4 | J24: =SUM(D24:G24)*H24+I24*2*H24 -> 34.82
A25: V | B25: TỔNG DÂY Cu/PVC 35mm2 | J25: =SUM(J26:J27) -> 22.856 | L25: =SUM(J25:K25) -> 22.856
A26: 1 | B26: Từ tủ DB-T1 -> DB-AC | C26: MEP-PW-01,04 | D26: =$I$9 -> 3.5 | E26: 1.4 | F26: =(1.23+1.753+0.268)+5 -> 8.251 | H26: 1 | I26: 0.5 | J26: =SUM(D26:G26)*H26+I26*2*H26 -> 14.151
B27: Trục đứng đi trong thang, máng cáp | C27: MEP-PW-05 | F27: =0.6+0.15+3.65*2+0.655 -> 8.705 | H27: 1 | J27: =SUM(D27:G27)*H27+I27*2*H27 -> 8.705
A28: VI | B28: TỔNG DÂY Cu/XLPE/PVC 25mm2 | J28: =SUM(J29:J32) -> 155.816 | L28: =SUM(J28:K28) -> 155.816
A29: 1 | B29: Từ tủ DB-T1 -> DB-T2 | C29: MEP-PW-01,02 | D29: =$I$9 -> 3.5 | E29: =$I$10 -> 3.3 | F29: =(1.23+1.753+0.268)*2 -> 6.502 | H29: 4 | I29: 0.5 | J29: =SUM(D29:G29)*H29+0.2*2*H29 -> 54.808
B30: Trục đứng đi trong thang, máng cáp | C30: MEP-PW-05 | F30: =$I$7-$I$9+$I$10 -> 3.95 | H30: 4 | J30: =SUM(D30:G30)*H30+I30*2*H30 -> 15.8
A31: 2 | B31: Từ tủ DB-T1 -> DB-T3 | C31: MEP-PW-01,03 | D31: =$I$9 -> 3.5 | E31: =$I$10 -> 3.3 | F31: =(1.23+1.753+0.268)*2 -> 6.502 | H31: 4 | I31: 0.5 | J31: =SUM(D31:G31)*H31+0.2*2*H31 -> 54.808
B32: Trục đứng đi trong thang, máng cáp | C32: MEP-PW-05 | F32: =$I$7-$I$9+$I$8+$I$10 -> 7.6 | H32: 4 | J32: =SUM(D32:G32)*H32+I32*2*H32 -> 30.4
A33: IV | B33: TỔNG DÂY Cu/XLPE/PVC 16mm2 | J33: =SUM(J34:J38) -> 241.116 | L33: =SUM(J33:K33) -> 241.116
A34: 1 | B34: Từ DB-T1 -> DB-XLNT | C34: MEP-OD-01 | D34: =$I$9 -> 3.5 | E34: =$I$11 -> 2 | F34: =1.211*2+0.744+4+1.4+4.4 -> 12.966 | G34: =0.3+6+11+2.992+1.01+0.272 -> 21.574 | H34: 5 | I34: 0.5 | J34: =SUM(D34:G34)*H34+0.2*2*H34 -> 202.2
A35: 2 | B35: Từ tủ DB-T1 -> DB-T2 | C35: MEP-PW-01,02 | D35: =$I$9+$I$10 -> 6.8 | F35: =(1.211+1.753+0.268)*2 -> 6.464 | H35: 1 | I35: 0.5 | J35: =SUM(D35:G35)*H35+0.2*2*H35 -> 13.664
B36: Trục đứng đi trong thang, máng cáp | C36: MEP-PW-05 | F36: =$I$7-$I$9+$I$10 -> 3.95 | H36: 1 | J36: =SUM(D36:G36)*H36+I36*2*H36 -> 3.95
A37: 3 | B37: Từ tủ DB-T1 -> DB-T3 | C37: MEP-PW-01,03 | D37: =$I$9 -> 3.5 | E37: =$I$10 -> 3.3 | F37: =(1.23+1.753+0.268)*2 -> 6.502 | H37: 1 | I37: 0.5 | J37: =SUM(D37:G37)*H37+0.2*2*H37 -> 13.702
B38: Trục đứng đi trong thang, máng cáp | C38: MEP-PW-05 | F38: =$I$7-$I$9+$I$8+$I$10 -> 7.6 | H38: 1 | J38: =SUM(D38:G38)*H38+I38*2*H38 -> 7.6
A39: VI | B39: TỔNG DÂY Cu/XLPE/PVC 10mm2 | J39: =SUM(J40:J42) -> 173.625 | K39: =SUM(K40:K41) -> 0 | L39: =SUM(J39:K39) -> 173.625
A40: 1 | B40: Từ tủ DB-T1 -> DB-T4 | C40: MEP-PW-01,04 | D40: =$I$9 -> 3.5 | E40: 1.3 | F40: =1.23+1.753+0.268+5+0.5 -> 8.751 | H40: 5 | I40: =0.5 -> 0.5 | J40: =SUM(D40:G40)*H40+0.2*2*H40 -> 69.755
B41: Trục đứng đi trong thang, máng cáp | C41: MEP-PW-05 | F41: =$I$7-$I$9+$I$8*2+0.655 -> 8.605 | H41: 5 | J41: =SUM(D41:G41)*H41+I41*2*H41 -> 43.025
A42: 2 | B42: Từ tủ DB-T3 -> DB-IT | C42: MEP-PW-03 | D42: =$I$10 -> 3.3 | E42: =(1.58+$I$8-$I$10) -> 1.93 | F42: =(1.23+1.753+0.268)+0.333+0.734+1.196+1.025 -> 6.539 | H42: 5 | I42: 0.5 | J42: =SUM(D42:G42)*H42+0.2*2*H42 -> 60.845
A44: VI | B44: TỔNG DÂY Cu/XLPE/PVC 4.0mm2 | J44: =J45 -> 125.22 | K44: =K45 -> 0 | L44: =SUM(J44:K44) -> 125.22
A45: 1 | B45: Từ DB-T1 -> DB-BP | C45: MEP-OD-01 | D45: =$I$9 -> 3.5 | E45: =$I$11 -> 2 | F45: =1.211*2+0.744+4+1.4+4.4 -> 12.966 | G45: =0.3+6+11+0.7+2.992+1.01+0.272 -> 22.274 | H45: 3 | I45: 0.5 | J45: =SUM(D45:G45)*H45+I45*2*H45 -> 125.22
A46: 2 | B46: Ống điện PVC D25 | C46: MEP-OD-01 | E46: 2 | F46: =1.211+4 -> 5.211 | G46: =0.3+6+11+0.7 -> 18 | J46: =SUM(D46:G46) -> 25.211 | L46: =J46 -> 25.211
...

Sheet Trunking.
A2: BẢNG DIỄN GIẢI CÁP ĐIỆN NGUỒN TRONG NHÀ
A3: ='Cable Nguon'!A3:L3 -> CÔNG TRÌNH : THI CÔNG ………………
A4: ='Cable Nguon'!A4:L4 -> ĐỊA ĐIỂM: ………………
A5: ='Cable Nguon'!A5:L5 -> SỐ HỢP ĐỒNG: …………………
D7: Chiều cao tầng 1 | G7: =4.15 -> 4.15 | H7: Chiều cao trần tầng 1 | J7: 3.3
D8: Chiều cao tầng 2, 3 | G8: =3.65 -> 3.65 | H8: Chiều cao trần tầng 2, 3 | J8: 3.2
D9: Chiều cao Trunking điện - điện nhẹ Tầng 1 | G9: 3.4 | H9: Chiều cao tủ DB-T1 | J9: 2
D10: Chiều cao Trunking điện - điện nhẹ Tầng 2, 3 | G10: 3.3 | H10: Chiều cao tủ DB-T2, T3 | J10: 1.5
A11: STT | B11: TÊN LINE | C11: KÍ HIỆU BẢN VẼ | D11: TỪ TRUNKING / TRẦN XUỐNG TỦ ĐIỆN | E11: TRUNKING TRỤC ĐỨNG | F11: MẶT BẰNG ĐI NỔI TRÊN TRẦN | G11: SỐ LƯỢNG | H11: TỔNG | I11: HAO HỤT | J11: TỔNG CỘNG SAU HAO HỤT
A12: I.1 | B12: Trunking 200 x 100 + Nắp | J12: =SUM(J13:J25) -> 202.936
A13: 1 | B13: Tầng trệt | H13: =SUM(H14:H18) -> 99.063 | J13: =H13 -> 99.063
B14: trunking điện | C14: MEP-TR-01 | D14: =$G$9-$J$9 -> 1.4 | E14: 11 | F14: =1.109+3.529+1.958+22.506+6.587+1.863 -> 37.552 | H14: =SUM(D14:F14) -> 49.952
B15: trunking điện nhẹ | C15: MEP-TR-01 | F15: =1.734+(3.529-0.287)+26.634+2.1+1.582+0.518+0.332+0.987+0.463 -> 37.592 | H15: =SUM(D15:F15) -> 37.592
B16: trunking dùng cho nguồn từ trạm biến áp vào (Chi tiết 2) | C16: MEP-TR-05 | E16: 4.4 | H16: =SUM(D16:F16) -> 4.4
B17: trunking cấp nguồn cho tủ XLNT, tủ bơm (Chi tiết A) | C17: MEP-TR-05 | E17: =4.4+1.5 -> 5.9 | H17: =SUM(D17:F17) -> 5.9
B18: Hộp gain kỹ thuật (bọc đáy trunking trục đứng) | C18: MEP-TR-05 | F18: 1.219 | H18: =SUM(D18:F18) -> 1.219
A19: 2 | B19: Tầng 1 | H19: =SUM(H20:H21) -> 55.8 | J19: =H19 -> 55.8
B20: trunking điện | C20: MEP-TR-02 | D20: =$G$10-$J$10 -> 1.8 | F20: =1.109+3.529+1.958+19.22+1.863 -> 27.679 | H20: =SUM(D20:F20) -> 29.479
B21: trunking điện nhẹ | C21: MEP-TR-02 | F21: =1.734+(3.529-0.287)+19.245+2.1 -> 26.321 | H21: =SUM(D21:F21) -> 26.321
A22: 3 | B22: Tầng 2 | H22: =SUM(H23:H24) -> 8.24 | J22: =H22 -> 8.24
B23: trunking điện | C23: MEP-TR-03 | D23: =$G$10-$J$10 -> 1.8 | F23: =1.352+1.436 -> 2.788 | H23: =SUM(D23:F23) -> 4.588
B24: phòng IT | C24: MEP-TR-03 | F24: =1.1*2+1.452 -> 3.652 | H24: =SUM(D24:F24) -> 3.652
A25: 4 | B25: Tầng mái | C25: MEP-TR-04 | F25: =4.1+8.038+9.882+(1.05+0.5)*8+0.313+2.3+0.5+0.7+(0.2*4+0.4*2) -> 39.833 | H25: =SUM(D25:F25) -> 39.833 | J25: =H25 -> 39.833
A28: I.2 | B28: Trunking 400 x 100 + Nắp | J28: =H29 -> 11
B29: Trục đứng | C29: MEP-TR-05 | E29: 11 | H29: =SUM(D29:F29) -> 11
A30: I.3 | B30: Trunking 90 x 40 + Nắp | J30: =SUM(H31:H34) -> 378.905
B31: Tầng trệt | C31: MEP-TR-01 | F31: =4.4*12+1.1*8 -> 61.6 | H31: =SUM(D31:F31) -> 61.6 | K31: 12 dãy bàn
B32: Tầng 1 | C32: MEP-TR-02 | F32: =4.4*14+5.5*12+3.3*8+14*1.1 -> 169.4 | H32: =SUM(D32:F32) -> 169.4 | K32: 34 dãy bàn
B33: Tầng 2 | C33: MEP-TR-03 | F33: =4.4*6+6*3.3+5.5*14+14*1.1 -> 138.6 | H33: =SUM(D33:F33) -> 138.6 | K33: 26 dãy bàn
B34: phòng IT | C34: MEP-TR-03 | F34: =2.2+1.1+1.1*2+1+1.225+1.58 -> 9.305 | H34: =SUM(D34:F34) -> 9.305
A38: STT | B38: BẢNG TỔNG HỢP
A39: 1 | B39: Trunking 200 x 100 + Nắp | C39: =J12 -> 202.936
A40: 2 | B40: Trunking 400 x 100 + Nắp | C40: =J28 -> 11
A41: 3 | B41: Trunking 90 x 40 + Nắp | C41: =J30 -> 378.905
J43: ……, ngày……tháng……năm 2023
C44: ĐẠI DIỆN NHÀ THẦU THI CÔNG | J44: ĐẠI DIỆN CHỦ ĐẦU TƯ

Sheet Cable DHKK
A2: BẢNG DIỄN GIẢI CÁP ĐIỆN NGUỒN TRONG NHÀ
A3: =Trunking.!A3 -> CÔNG TRÌNH : THI CÔNG ………………
A4: =Trunking.!A4 -> ĐỊA ĐIỂM: ………………
A5: =Trunking.!A5 -> SỐ HỢP ĐỒNG: …………………
F6: Chiều cao tầng 1 | J6: 4.15 | K6: Chiều cao trần tầng 1 | M6: 3.3
F7: Chiều cao tầng 2, 3 | J7: =3.65 -> 3.65 | K7: Chiều cao trần tầng 2, 3 | M7: 3.2
F8: Chiều cao Trunking điện nhẹ Tầng 1 | J8: 3.4 | K8: Chiều cao tủ DB-T1 | M8: 2
F9: Chiều cao Trunking điện nhẹ Tầng 2, 3 | J9: 3.3 | K9: Chiều cao tủ DB-T2, T3 | M9: 1.5
A12: STT | B12: TÊN LINE | C12: KÍ HIỆU BẢN VẼ | D12: TỪ TRUNKING / TRẦN ĐẾN TỦ ĐIỆN | E12: TỪ TRUNKING/ TRẦN ĐẾN THIẾT BỊ | F12: MẶT BẰNG DÂY ĐIỆN ĐI NỔI TRÊN TRẦN | G12: SỐ LƯỢNG THẾT BỊ | H12: DÂY CHỜ ĐẤU NỐI | I12: DÂY ĐIỆN ĐI TRONG TRUNKING | J12: SỐ LƯỢNG DÂY | K12: TỔNG DÂY | L12: HAO HỤT | M12: TỔNG CỘNG SAU HAO HỤT
A13: I.1 | B13: DÂY 2.5mm2 cho nguồn máy lạnh | M13: =SUM(M14:M19) -> 1218.038
A14: 1 | B14: Dàn lạnh Tầng trệt | C14: MEP-NL-01 | D14: =J8 -> 3.4 | E14: =J6-M6 -> 0.85 | F14: =1.123*3+4.8+2.985*2+1.815+1.609*3+(0.7+0.687+1.328)*3+4.315+4.956*2+0.425+0.709+3.745+0.676+1.175*3+2.197+2.603*2+4.8+1.557*3+1.557+2.953*3+3.13+2.025+2.268*2+4.8+1.549*2 -> 97.112 | G14: 12 | H14: 0.5 | I14: =(2.903+1.309+0.824+1.191)*2+15.992 -> 28.446 | J14: 3 | K14: =(D14+F14+I14)*J14+(G14*(E14+0.3*2))*J14 -> 439.074 | M14: =K14 -> 439.074
A15: 2 | B15: Dàn lạnh Tầng 1 | C15: MEP-NL-02 | D15: =J9 -> 3.3 | E15: =J7-M7 -> 0.45 | F15: =0.975*3+4.751+2.768*2+2.029*2+5.783+1.797+1.609*4+1.548+2.068+4.951+1.026*3+2.588+2.21*2+4.8+1.557*3+2.593*3+2.137*3+3.041+1.871*2+4.8 -> 85.183 | G15: 11 | H15: 0.5 | I15: =(2.903+1.309+0.824+1.191)*2+15.992 -> 28.446 | J15: 3 | K15: =(D15+F15+I15)*J15+(G15*(E15+0.3*2))*J15 -> 385.437 | M15: =K15 -> 385.437
A16: 3 | B16: Dàn lạnh Tầng 2 | C16: MEP-NL-03 | M16: =SUM(K17:K19) -> 393.527
B17: dàn lạnh khu văn phòng + phòng P.TGD | D17: =J9 -> 3.3 | E17: =J7-M7 -> 0.45 | F17: =(0.941*3+4.787+3.013*2+1.791+1.609*3+0.687+1.84+1.012*2+2.608+2.057+1.828)+(0.992*3+2.238+2.564*2+4.8+1.557*3+2.953*3+1.723+3.139+2.19*2+4.8+1.84+16.679) -> 92.531 | G17: 9 | H17: 0.5 | I17: =1.456*2+1.191*2 -> 5.294 | J17: 3 | K17: =(D17+F17+I17)*J17+(G17*(E17+0.3))*J17 -> 323.625
B18: 3 dàn lạnh treo tường phòng IT | D18: =1.58+0.6 -> 2.18 | E18: =M7-2.75 -> 0.45 | F18: =+((1.225+1.73+2.329)*2+1.384) -> 11.952 | G18: 3 | H18: 0.3 | J18: 3 | K18: =(D18+F18+I18)*J18+(G18*(E18+H18))*J18 -> 49.146
B19: bộ điều khiển trung tâm | D19: =1.58+0.6 -> 2.18 | E19: =M7-1.3 -> 1.9 | F19: =1.225+1.73+2.329+0.2+0.514 -> 5.998 | G19: 1 | H19: 0.3 | J19: 2 | K19: =(D19+F19+I19)*J19+(G19*(E19+H19))*J19 -> 20.756
A21: 4 | B21: Ống điện PVC D20 = Tổng dây/3(số dây) - dây điện đi trong Trunking - dây chờ đấu nối | K21: =SUM(K14:K19)/3-(SUM(I14:I19)+SUM(H14:H19)) -> 341.72667 | M21: =K21 -> 341.72667
A22: I.2 | B22: DÂY 16mm2 cấp nguồn cho dàn nóng máy lạnh | M22: =SUM(M23:M31) -> 716.72
B23: Dàn nóng Tầng mái | M23: =SUM(K24:K31) -> 716.72
B24: dàn nóng 1 tổ 1F+2F | C24: MEP-NL-04 | D24: 1.4 | E24: =0.3+1.2+1 -> 2.5 | G24: 1 | H24: 0.5 | I24: =4.369+0.428+2.542+1.05+0.44 -> 8.829 | J24: 5 | K24: =(D24+H24+E24+0.3+I24)*J24*G24 -> 67.645
B25: dàn nóng 2 tổ 1F+2F | C25: MEP-NL-04 | D25: 1.4 | E25: =0.3+1.2+1 -> 2.5 | G25: 1 | H25: 0.5 | I25: =4.369+0.428+2.542+1.05+0.44+2.05 -> 10.879 | J25: 5 | K25: =(D25+H25+E25+0.3+I25)*J25*G25 -> 77.895
B26: dàn nóng 3 tổ 1F+2F | C26: MEP-NL-04 | D26: 1.4 | E26: =0.3+1.2+1 -> 2.5 | G26: 1 | H26: 0.5 | I26: =4.369+0.428+2.542+1.05+0.44+2.05*2 -> 12.929 | J26: 5 | K26: =(D26+H26+E26+0.3+I26)*J26*G26 -> 88.145
B27: dàn nóng 4 tổ 1F+2F | C27: MEP-NL-04 | D27: 1.4 | E27: =0.3+1.2+1 -> 2.5 | G27: 1 | H27: 0.5 | I27: =4.369+0.428+2.542+1.05+0.44+2.05*3 -> 14.979 | J27: 5 | K27: =(D27+H27+E27+0.3+I27)*J27*G27 -> 98.395
B28: dàn nóng 1 tổ 2F+3F | C28: MEP-NL-04 | D28: 1.4 | E28: =0.3+1.2+1 -> 2.5 | G28: 1 | H28: 0.5 | I28: =4.369+1.144+4.454+1.05+0.44 -> 11.457 | J28: 5 | K28: =(D28+H28+E28+0.3+I28)*J28*G28 -> 80.785
B29: dàn nóng 2 tổ 2F+3F | C29: MEP-NL-04 | D29: 1.4 | E29: =0.3+1.2+1 -> 2.5 | G29: 1 | H29: 0.5 | I29: =4.369+1.144+4.454+1.05+0.44+2.05 -> 13.507 | J29: 5 | K29: =(D29+H29+E29+0.3+I29)*J29*G29 -> 91.035
B30: dàn nóng 3 tổ 2F+3F | C30: MEP-NL-04 | D30: 1.4 | E30: =0.3+1.2+1 -> 2.5 | G30: 1 | H30: 0.5 | I30: =4.369+1.144+4.454+1.05+0.44+2.05*2 -> 15.557 | J30: 5 | K30: =(D30+H30+E30+0.3+I30)*J30*G30 -> 101.285
B31: dàn nóng 4 tổ 2F+3F | C31: MEP-NL-04 | D31: 1.4 | E31: =0.3+1.2+1 -> 2.5 | G31: 1 | H31: 0.5 | I31: =4.369+1.144+4.454+1.05+0.44+2.05*3 -> 17.607 | J31: 5 | K31: =(D31+H31+E31+0.3+I31)*J31*G31 -> 111.535
A32: I.3 | B32: DÂY 1.5mm2 khiển từ máy lạnh đến remote | M32: =SUM(M33:M42) -> 1023.26
A33: 1 | B33: Dàn lạnh Tầng trệt | M33: =SUM(K34:K35) -> 299.872
B34: mặt bằng kéo cáp khiển từ dàn lạnh | C34: MEP-RE-01 | E34: =J6-M6 -> 0.85 | F34: =0.54*3+4.8+4.8*2+(2.005+2.852)*3+2.368+2.295+0.874*2+4.17+(2.736+2.471)*2+2.4+1.857+1.38*2+4.8+2.306*2+0.884*3+4.8*3+(1.428+2.195)*3 -> 95.936 | G34: 12 | H34: 0.5 | J34: 2 | K34: =(E34+H34)*G34*J34+F34*J34 -> 224.272
B35: trục đứng cáp khiển đến remote gắn tường | C35: MEP-RE-01 | E35: =J6-1.3 -> 2.85 | G35: 12 | H35: 0.3 | J35: 2 | K35: =(E35+H35)*G35*J35+F35*J35 -> 75.6
A36: 2 | B36: Dàn lạnh Tầng 1 | M36: =SUM(K37:K38) -> 322.526
B37: mặt bằng kéo cáp khiển từ dàn lạnh | C37: MEP-RE-02 | E37: =J7-M7 -> 0.45 | F37: =1.53*3+4.808+4.762*2+(3.487)*3+2.295+1.874+1.63*4+2.531+2.23+(1.176+3.527*2+0.641)*3+4.8*6+1.508*3+5.631*3 -> 121.663 | G37: 11 | H37: 0.5 | J37: 2 | K37: =(E37+H37)*G37*J37+F37*J37 -> 264.226
B38: trục đứng cáp khiển đến remote gắn tường | C38: MEP-RE-02 | E38: =J7-1.3 -> 2.35 | G38: 11 | H38: 0.3 | J38: 2 | K38: =(E38+H38)*G38*J38+F38*J38 -> 58.3
A39: 3 | B39: Dàn lạnh Tầng 2 | M39: =SUM(K40:K41) -> 267.732
B40: mặt bằng kéo cáp khiển từ dàn lạnh | C40: MEP-RE-03 | E40: =J7-M7 -> 0.45 | F40: =1.02*3+4.8*3+(2.968+1.321)*3+1.027+2.393+2.194+0.873*3+0.3*2+(3.03*5+4.783*4+4.8*2+5.15*2+1.508*3) -> 97.866 | G40: 10 | H40: 0.5 | J40: 2 | K40: =(E40+H40)*G40*J40+F40*J40 -> 214.732
B41: trục đứng cáp khiển đến remote gắn tường | C41: MEP-RE-03 | E41: =J7-1.3 -> 2.35 | G41: 10 | H41: 0.3 | J41: 2 | K41: =(E41+H41)*G41*J41+F41*J41 -> 53
A42: 4 | B42: Dàn lạnh Phòng IT | C42: MEP-RE-03 | E42: =J7-M7 -> 0.45 | F42: =1.272+(1.978+2.308+0.333+1.188+1.552+1.305+0.367+1.5+0.524+0.167)*2+1.01 -> 24.726 | G42: 2 | H42: 0.5 | J42: 5 | K42: =(E42+H42)*G42*J42+F42*J42 -> 133.13 | M42: =K42 -> 133.13
B43: Tổng đầu chờ = [∑ số thiết bị máy lạnh x (0.3+cao độ từ trần bê tông xuống trần)]
A44: 5 | B44: Ống điện PVC D20 = Tổng dây/3(số dây) - dây điện đi trong Trunking - dây chờ đấu nối | K44: =SUM(K34:K42)/2-SUM(I37:I42)-SUM(H34:H42) -> 508.73 | M44: =K44 -> 508.73
...

Sheet DMBV MEP
A1: Stt | B1: Nội Dung | C1: Số lượng | D1: Mã Bản Vẽ | E1: Ghi Chú
A2: 1 | B2: DANH MỤC BẢN VẼ | C2: 1
A3: 2 | B3: KÍ HIỆU CHUNG | C3: 1 | D3: MEP-GC-01
A4: 3 | B4: SƠ ĐỒ NGUYÊN LÝ TỦ ĐIỆN DB-T1 | C4: 1 | D4: MEP-NL-01
A5: 4 | B5: SƠ ĐỒ NGUYÊN LÝ TỦ ĐIỆN DB-T2 | C5: 1 | D5: MEP-NL-02
A6: 5 | B6: SƠ ĐỒ NGUYÊN LÝ TỦ ĐIỆN DB-T3 | C6: 1 | D6: MEP-NL-03
A7: 6 | B7: SƠ ĐỒ NGUYÊN LÝ TỦ ĐIỆN DB-T4, DB-IT | C7: 1 | D7: MEP-NL-04
A8: 7 | B8: SƠ ĐỒ NGUYÊN LÝ TỦ ĐIỆN DB-AC | C8: 1 | D8: MEP-NL-05
A9: 8 | B9: Mặt bằng bố trí cấp nguồn tủ DB-T1, DB-XLNT, DB-BP, tín hiệu phao điện | C9: 1 | D9: MEP-OD-01
A10: 9 | B10: Mặt bằng bố trí tín hiệu phao điện bồn nước | C10: 1 | D10: MEP-OD-02
A11: 10 | B11: Mặt bằng lắp đặt ống - cáp khiển remote máy lạnh tầng trệt | C11: 1 | D11: MEP-RE-01
A12: 11 | B12: Mặt bằng lắp đặt ống - cáp khiển remote máy lạnh tầng 1 | C12: 1 | D12: MEP-RE-02
A13: 12 | B13: Mặt bằng lắp đặt ống - cáp khiển remote máy lạnh tầng 2 | C13: 1 | D13: MEP-RE-03
A14: 13 | B14: Mặt bằng lắp đặt ống - cáp khiển máy lạnh tầng mái | C14: 1 | D14: MEP-RE-04
... A88: 87 | B88: Mặt bằng bố trí đi ống - cáp Cat 6 kho hồ sơ Tôn Hoa Sen | C88: 1 | D88: MEP-DN-04
